<?xml version="1.0" ?>
<!-- =================================================================================== -->
<!-- |    This document was autogenerated by xacro from /home/bot/catkin_ws/src/dp_ptu_46_description/dp_ptu_46.urdf.xacro | -->
<!-- |    EDITING THIS FILE BY HAND IS NOT RECOMMENDED                                 | -->
<!-- =================================================================================== -->
<robot name="dp_ptu_46" xmlns:xacro="http://www.ros.org/wiki/xacro">
  <link name="ptu_base_plate_link">
    <visual>
      <origin rpy="0 0 0" xyz="-0.035 0 0.0025"/>
      <geometry>
        <box size="0.17 0.142 0.005"/>
      </geometry>
      <material name="black">
        <color rgba="0.2 0.2 0.2 1"/>
      </material>
    </visual>
  </link>
  <joint name="ptu_base_plate_joint" type="fixed">
    <parent link="ptu_base_plate_link"/>
    <child link="ptu_base_link"/>
    <origin rpy="0 0 0" xyz="0.0 0.0 0.0"/>
  </joint>
  <link name="ptu_base_link">
    </link>
  <joint name="ptu_base_joint" type="fixed">
    <parent link="ptu_base_link"/>
    <child link="ptu_pan_link"/>
    <origin rpy="0 0 0" xyz="0.0 0 0.005"/>
  </joint>
  <link name="ptu_pan_link">
    <visual>
      <origin rpy="0 0 0" xyz="0 0.0 0.025"/>
      <geometry>
        <mesh filename="package://dp_ptu_46_description/meshes/pan.dae"/>
      </geometry>
    </visual>
    <collision>
      <origin xyz="0 0.0115 0.047"/>
      <geometry>
        <box size="0.154 0.177 0.094"/>
      </geometry>
    </collision>
  </link>
  <joint name="ptu_pan_joint" type="revolute">
    <parent link="ptu_base_link"/>
    <child link="ptu_tilt_link"/>
    <origin rpy="0 0 0" xyz="-0.00436 -0.0067 0.03"/>
    <limit effort="100.0" lower="-2.775" upper="2.775" velocity="1.0"/>
    <axis xyz="0 0 1"/>
  </joint>
  <link name="ptu_tilt_link">
    <visual>
      <origin rpy="0 0 0" xyz="0.00436 0.0067 0.0"/>
      <geometry>
        <mesh filename="package://dp_ptu_46_description/meshes/tilt.dae"/>
      </geometry>
    </visual>
    <collision>
      <origin xyz="0 0.0115 0.047"/>
      <geometry>
        <box size="0.154 0.177 0.094"/>
      </geometry>
    </collision>
  </link>
  <joint name="ptu_tilt_joint" type="revolute">
    <parent link="ptu_tilt_link"/>
    <child link="ptu_mount_link"/>
    <origin rpy="0 0 0" xyz="0.0 0 0.0659"/>
    <limit effort="100.0" lower="-1.396" upper="0.541" velocity="1.0"/>
    <axis xyz="0 -1 0"/>
  </joint>
  <link name="ptu_mount_link">
    <visual>
      <origin rpy="0 0 0" xyz="0.00436 0.0067 -0.0659"/>
      <geometry>
        <mesh filename="package://dp_ptu_46_description/meshes/mount.dae"/>
      </geometry>
    </visual>
    <collision>
      <origin xyz="0 0.0115 0.047"/>
      <geometry>
        <box size="0.154 0.177 0.094"/>
      </geometry>
    </collision>
  </link>
</robot>
