<?xml version="1.0" ?>
<!-- =================================================================================== -->
<!-- |    This document was autogenerated by xacro from /home/qasim/catkin_ws/src/control_test/urdf/testRobot.urdf.xacro | -->
<!-- |    EDITING THIS FILE BY HAND IS NOT RECOMMENDED                                 | -->
<!-- =================================================================================== -->
<robot name="myTestRobot" xmlns:xacro="http://www.ros.org/wiki/xacro">
  <link name="fixed_base">
    <visual>
      <origin rpy="0 0 0" xyz="0 0 0.54"/>
      <geometry>
        <box size="0.34 0.31 1.0"/>
      </geometry>
    </visual>
    <collision>
      <origin rpy="0 0 0" xyz="0 0 0.54"/>
      <geometry>
        <box size="0.34 0.31 1.0"/>
      </geometry>
    </collision>
    <inertial>
      <origin rpy="0 0 0" xyz="0.0 0.0 0.5"/>
      <mass value="12"/>
      <!-- inretia tensor for solid cuboid: m=12, h=1.12, d=0.49, w=0.41 -->
      <inertia ixx="1.4225" ixy="0" ixz="0" iyy="1.4945" iyz="0" izz="0.4082"/>
    </inertial>
  </link>
  <joint name="right_arm_joint" type="fixed">
    <parent link="fixed_base"/>
    <child link="right_arm_base_link"/>
    <!--origin rpy="0 0 0" xyz="0 0.25 0.05"/-->
    <origin rpy="1.5708 -1.5708 0" xyz="0.067 -0.162 0.8"/>
  </joint>
  <link name="right_arm_base_link">
    <visual>
      <origin rpy="0 0 0" xyz="0 0 0"/>
      <geometry>
        <mesh filename="package://cyton_gamma_1500_description/meshes/base.dae"/>
      </geometry>
    </visual>
    <inertial>
      <mass value="100.0"/>
      <origin rpy="0 0 0" xyz="0 0 0"/>
      <inertia ixx="1.1027" ixy="0" ixz="0" iyy="1.1027" iyz="0" izz="1.1027"/>
    </inertial>
    <collision>
      <origin xyz="0 0.0115 0.047"/>
      <geometry>
        <box size="0.154 0.177 0.094"/>
      </geometry>
    </collision>
  </link>
  <joint name="right_arm_shoulder_roll_joint" type="revolute">
    <parent link="right_arm_base_link"/>
    <child link="right_arm_shoulder_roll"/>
    <origin rpy="0 0 0" xyz="0 0 0.05315"/>
    <limit effort="100.0" lower="-2.618" upper="2.618" velocity="1.0"/>
    <axis xyz="0 0 1"/>
  </joint>
  <link name="right_arm_shoulder_roll">
    <visual>
      <origin rpy="1.5708 0 0.384" xyz="0 0 0"/>
      <geometry>
        <mesh filename="package://cyton_gamma_1500_description/meshes/shoulder_roll.dae"/>
      </geometry>
    </visual>
    <collision>
      <origin xyz="0.0 0.069 0.0587"/>
      <geometry>
        <box size="0.09829 0.18143 0.08392"/>
      </geometry>
    </collision>
    <inertial>
      <mass value="50.0"/>
      <origin rpy="0 0 0" xyz="0 0 0"/>
      <inertia ixx=".1027" ixy="0" ixz="0" iyy=".1027" iyz="0" izz=".1027"/>
    </inertial>
  </link>
  <joint name="right_arm_shoulder_pitch_joint" type="revolute">
    <parent link="right_arm_shoulder_roll"/>
    <child link="right_arm_shoulder_pitch"/>
    <origin rpy="0 0 0" xyz="0.0205 0 0.12435"/>
    <limit effort="100.0" lower="-1.8326" upper="1.8326" velocity="1.0"/>
    <axis xyz="1 0 0"/>
  </joint>
  <transmission name="right_arm_tran1">
    <type>transmission_interface/SimpleTransmission</type>
    <joint name="right_arm_shoulder_roll_joint">
      <hardwareInterface>hardware_interface/PositionJointInterface</hardwareInterface>
    </joint>
    <actuator name="right_arm_motor1">
      <hardwareInterface>hardware_interface/PositionJointInterface</hardwareInterface>
    </actuator>
  </transmission>
  <link name="right_arm_shoulder_pitch">
    <visual>
      <origin rpy="1.5708 0 0" xyz="0 0 0"/>
      <geometry>
        <mesh filename="package://cyton_gamma_1500_description/meshes/shoulder_pitch.dae"/>
      </geometry>
    </visual>
    <collision>
      <origin xyz="-0.02 0.0 0.0"/>
      <geometry>
        <sphere radius="0.055"/>
        <!--box size="0.098 0.08 0.11"/-->
      </geometry>
    </collision>
    <inertial>
      <mass value="20.0"/>
      <origin rpy="0 0 0" xyz="0 0 0"/>
      <inertia ixx=".0827" ixy="0" ixz="0" iyy=".0827" iyz="0" izz=".0827"/>
    </inertial>
  </link>
  <joint name="right_arm_shoulder_yaw_joint" type="revolute">
    <parent link="right_arm_shoulder_pitch"/>
    <child link="right_arm_shoulder_yaw"/>
    <origin rpy="0 0 0" xyz="-0.0215 -0.0205 0.1255"/>
    <limit effort="100.0" lower="-1.8326" upper="1.8326" velocity="1.0"/>
    <axis xyz="0 -1 0"/>
  </joint>
  <transmission name="right_arm_tran2">
    <type>transmission_interface/SimpleTransmission</type>
    <joint name="right_arm_shoulder_pitch_joint">
      <hardwareInterface>hardware_interface/PositionJointInterface</hardwareInterface>
    </joint>
    <actuator name="right_arm_motor2">
      <hardwareInterface>hardware_interface/PositionJointInterface</hardwareInterface>
    </actuator>
  </transmission>
  <link name="right_arm_shoulder_yaw">
    <visual>
      <origin rpy="1.5708 0 -1.5708" xyz="0 0 0.0"/>
      <geometry>
        <mesh filename="package://cyton_gamma_1500_description/meshes/shoulder_yaw.dae"/>
      </geometry>
    </visual>
    <collision>
      <origin xyz=" -0.002 0.02 -0.01"/>
      <geometry>
        <sphere radius="0.055"/>
        <!--box size="0.08 0.1 0.11"/-->
      </geometry>
    </collision>
    <inertial>
      <mass value="10.0"/>
      <origin rpy="0 0 0" xyz="0 0 0"/>
      <inertia ixx=".0627" ixy="0" ixz="0" iyy=".0627" iyz="0" izz=".0627"/>
    </inertial>
  </link>
  <transmission name="right_arm_tran3">
    <type>transmission_interface/SimpleTransmission</type>
    <joint name="right_arm_shoulder_yaw_joint">
      <hardwareInterface>hardware_interface/PositionJointInterface</hardwareInterface>
    </joint>
    <actuator name="right_arm_motor3">
      <hardwareInterface>hardware_interface/PositionJointInterface</hardwareInterface>
    </actuator>
  </transmission>
  <joint name="right_arm_elbow_pitch_joint" type="revolute">
    <parent link="right_arm_shoulder_yaw"/>
    <child link="right_arm_elbow_pitch"/>
    <origin rpy="0 0 0" xyz="0.018 0.0206 0.1158"/>
    <limit effort="100.0" lower="-1.8326" upper="1.8326" velocity="1.0"/>
    <axis xyz="1 0 0"/>
  </joint>
  <link name="right_arm_elbow_pitch">
    <visual>
      <origin rpy="1.5708 0 3.1416" xyz="0 0 0"/>
      <geometry>
        <mesh filename="package://cyton_gamma_1500_description/meshes/elbow_pitch.dae"/>
      </geometry>
    </visual>
    <collision>
      <origin xyz="-0.022 0.0 -0.006"/>
      <geometry>
        <sphere radius="0.055"/>
        <!--box size="0.09 0.1 0.11"/-->
      </geometry>
    </collision>
    <inertial>
      <mass value="10.0"/>
      <origin rpy="0 0 0" xyz="0 0 0"/>
      <inertia ixx=".0327" ixy="0" ixz="0" iyy=".0327" iyz="0" izz=".0327"/>
    </inertial>
  </link>
  <transmission name="right_arm_tran4">
    <type>transmission_interface/SimpleTransmission</type>
    <joint name="right_arm_elbow_pitch_joint">
      <hardwareInterface>hardware_interface/PositionJointInterface</hardwareInterface>
    </joint>
    <actuator name="right_arm_motor4">
      <hardwareInterface>hardware_interface/PositionJointInterface</hardwareInterface>
    </actuator>
  </transmission>
  <joint name="right_arm_elbow_yaw_joint" type="revolute">
    <parent link="right_arm_elbow_pitch"/>
    <child link="right_arm_elbow_yaw"/>
    <origin rpy="0 0 0" xyz="-0.0171 -0.018 0.09746"/>
    <limit effort="100.0" lower="-1.8326" upper="1.8326" velocity="1.0"/>
    <axis xyz="0 -1 0"/>
  </joint>
  <link name="right_arm_elbow_yaw">
    <visual>
      <origin rpy="1.5708 0 1.5708" xyz="0 0 0"/>
      <geometry>
        <mesh filename="package://cyton_gamma_1500_description/meshes/elbow_yaw.dae"/>
      </geometry>
    </visual>
    <collision>
      <origin xyz="0.0 0.025 0.0"/>
      <geometry>
        <sphere radius="0.05"/>
      </geometry>
    </collision>
    <inertial>
      <mass value="10.0"/>
      <origin rpy="0 0 0" xyz="0 0 0"/>
      <inertia ixx=".0227" ixy="0" ixz="0" iyy=".0227" iyz="0" izz=".0227"/>
    </inertial>
  </link>
  <transmission name="right_arm_tran5">
    <type>transmission_interface/SimpleTransmission</type>
    <joint name="right_arm_elbow_yaw_joint">
      <hardwareInterface>hardware_interface/PositionJointInterface</hardwareInterface>
    </joint>
    <actuator name="right_arm_motor5">
      <hardwareInterface>hardware_interface/PositionJointInterface</hardwareInterface>
    </actuator>
  </transmission>
  <joint name="right_arm_wrist_pitch_joint" type="revolute">
    <parent link="right_arm_elbow_yaw"/>
    <child link="right_arm_wrist_pitch"/>
    <origin rpy="0 0 0" xyz="0.02626 0.018 0.0718"/>
    <limit effort="100.0" lower="-1.8326" upper="1.8326" velocity="1.0"/>
    <axis xyz="-1 0 0"/>
  </joint>
  <link name="right_arm_wrist_pitch">
    <visual>
      <origin rpy="1.5708 0 1.5708" xyz="0 0 0"/>
      <geometry>
        <mesh filename="package://cyton_gamma_1500_description/meshes/wrist_pitch.dae"/>
      </geometry>
    </visual>
    <collision>
      <origin xyz="-0.02 0.0 0.0"/>
      <geometry>
        <box size="0.07 0.06 0.11"/>
      </geometry>
    </collision>
    <inertial>
      <mass value="10.0"/>
      <origin rpy="0 0 0" xyz="0 0 0"/>
      <inertia ixx=".0127" ixy="0" ixz="0" iyy=".0127" iyz="0" izz=".0127"/>
    </inertial>
  </link>
  <transmission name="right_arm_tran6">
    <type>transmission_interface/SimpleTransmission</type>
    <joint name="right_arm_wrist_pitch_joint">
      <hardwareInterface>hardware_interface/PositionJointInterface</hardwareInterface>
    </joint>
    <actuator name="right_arm_motor6">
      <hardwareInterface>hardware_interface/PositionJointInterface</hardwareInterface>
    </actuator>
  </transmission>
  <joint name="right_arm_wrist_roll_joint" type="revolute">
    <parent link="right_arm_wrist_pitch"/>
    <child link="right_arm_wrist_roll"/>
    <origin rpy="0 0 0" xyz="-0.026255 0 0.051425"/>
    <limit effort="100.0" lower="-2.61799" upper="2.61799" velocity="1.0"/>
    <axis xyz="0 0 1"/>
  </joint>
  <link name="right_arm_wrist_roll">
    <visual>
      <origin rpy="3.1416 0 -1.5708" xyz="0 0 0"/>
      <geometry>
        <mesh filename="package://cyton_gamma_1500_description/meshes/wrist_roll.dae"/>
      </geometry>
    </visual>
    <collision>
      <origin xyz="0.0 0.008 0.04"/>
      <geometry>
        <box size="0.08 0.06 0.08"/>
      </geometry>
    </collision>
    <inertial>
      <mass value="10.0"/>
      <origin rpy="0 0 0" xyz="0 0 0"/>
      <inertia ixx=".0027" ixy="0" ixz="0" iyy=".0027" iyz="0" izz=".0027"/>
    </inertial>
  </link>
  <transmission name="right_arm_tran7">
    <type>transmission_interface/SimpleTransmission</type>
    <joint name="right_arm_wrist_roll_joint">
      <hardwareInterface>hardware_interface/PositionJointInterface</hardwareInterface>
    </joint>
    <actuator name="right_arm_motor7">
      <hardwareInterface>hardware_interface/PositionJointInterface</hardwareInterface>
    </actuator>
  </transmission>
  <joint name="right_arm_gripper_joint" type="prismatic">
    <parent link="right_arm_wrist_roll"/>
    <child link="right_arm_gripper_finger1"/>
    <origin rpy="0 0 0" xyz="-0.01331 0.00485 0.077225"/>
    <limit effort="100.0" lower="-0.008" upper="0.008" velocity="1.0"/>
    <axis xyz="1 0 0"/>
  </joint>
  <link name="right_arm_gripper_finger1">
    <visual>
      <origin rpy="0 0 0" xyz="0 0 0"/>
      <geometry>
        <mesh filename="package://cyton_gamma_1500_description/meshes/gripper_finger1.dae"/>
      </geometry>
    </visual>
    <collision>
      <!--origin xyz="-0.0167 0.0172 0.7254"/-->
      <origin xyz="0.0 0.008 0.04"/>
      <geometry>
        <box size="0.015 0.0229 0.0475"/>
      </geometry>
    </collision>
    <inertial>
      <!--origin rpy="0 0 0" xyz="0.0034 0.0096 0.017"/-->
      <origin rpy="0 0 0" xyz="0 0 0"/>
      <mass value="0.035"/>
      <!-- inretia tensor for solid cuboid: m=0.035, h=0.0323, w=0.01469, d=0.0224 -->
      <inertia ixx="4.5064e-06" ixy="0" ixz="0" iyy="3.6723e-06" iyz="0" izz="2.0929e-06"/>
    </inertial>
  </link>
  <transmission name="right_arm_tran8">
    <type>transmission_interface/SimpleTransmission</type>
    <joint name="right_arm_gripper_joint">
      <hardwareInterface>hardware_interface/PositionJointInterface</hardwareInterface>
    </joint>
    <actuator name="right_arm_motor8">
      <hardwareInterface>hardware_interface/PositionJointInterface</hardwareInterface>
    </actuator>
  </transmission>
  <joint name="right_arm_gripper_joint2" type="prismatic">
    <parent link="right_arm_wrist_roll"/>
    <child link="right_arm_gripper_finger2"/>
    <origin rpy="0 0 0" xyz="0.0098 0.00485 0.077225"/>
    <limit effort="100.0" lower="-0.008" upper="0.008" velocity="1.0"/>
    <mimic joint="right_arm_gripper_joint" multiplier="-1"/>
    <axis xyz="1 0 0"/>
  </joint>
  <link name="right_arm_gripper_finger2">
    <visual>
      <origin rpy="0 0 0" xyz="0 0 0"/>
      <geometry>
        <mesh filename="package://cyton_gamma_1500_description/meshes/gripper_finger2.dae"/>
      </geometry>
    </visual>
    <collision>
      <!--origin xyz="0.0132 0.0172 0.7254"/-->
      <origin xyz="0.0 0.008 0.04"/>
      <geometry>
        <box size="0.015 0.0229 0.0475"/>
      </geometry>
    </collision>
    <inertial>
      <!--origin rpy="0 0 0" xyz="0.0034 0.0096 0.017"/-->
      <origin rpy="0 0 0" xyz="0 0 0"/>
      <mass value="0.035"/>
      <!-- inretia tensor for solid cuboid: m=0.035, h=0.0323, w=0.01469, d=0.0224 -->
      <inertia ixx="4.5064e-06" ixy="0" ixz="0" iyy="3.6723e-06" iyz="0" izz="2.0929e-06"/>
    </inertial>
  </link>
  <transmission name="right_arm_tran9">
    <type>transmission_interface/SimpleTransmission</type>
    <joint name="right_arm_gripper_joint2">
      <hardwareInterface>hardware_interface/PositionJointInterface</hardwareInterface>
    </joint>
    <actuator name="right_arm_motor9">
      <hardwareInterface>hardware_interface/PositionJointInterface</hardwareInterface>
    </actuator>
  </transmission>
  <!-- virtual end-effector -->
  <joint name="right_arm_virtual_endeffector_joint" type="fixed">
    <parent link="right_arm_wrist_roll"/>
    <child link="right_arm_virtual_endeffector"/>
    <origin rpy="0 0 0" xyz="-0.002316 0.0079 0.079425"/>
  </joint>
  <link name="right_arm_virtual_endeffector">
    <visual>
      <origin rpy="0 0 0" xyz="0 0 0"/>
      <geometry>
        <sphere radius="0.002"/>
      </geometry>
      <material name="grey">
        <color rgba="0.7 0.7 0.7 0.8"/>
      </material>
    </visual>
  </link>
  <joint name="left_arm_joint" type="fixed">
    <parent link="fixed_base"/>
    <child link="left_arm_base_link"/>
    <!--origin rpy="0 0 0" xyz="0 -0.3 0.05"/-->
    <origin rpy="-1.5708 1.5708 0" xyz="0.067 0.162 0.8"/>
  </joint>
  <link name="left_arm_base_link">
    <visual>
      <origin rpy="0 0 0" xyz="0 0 0"/>
      <geometry>
        <mesh filename="package://cyton_gamma_1500_description/meshes/base.dae"/>
      </geometry>
    </visual>
    <inertial>
      <mass value="100.0"/>
      <origin rpy="0 0 0" xyz="0 0 0"/>
      <inertia ixx="1.1027" ixy="0" ixz="0" iyy="1.1027" iyz="0" izz="1.1027"/>
    </inertial>
    <collision>
      <origin xyz="0 0.0115 0.047"/>
      <geometry>
        <box size="0.154 0.177 0.094"/>
      </geometry>
    </collision>
  </link>
  <joint name="left_arm_shoulder_roll_joint" type="revolute">
    <parent link="left_arm_base_link"/>
    <child link="left_arm_shoulder_roll"/>
    <origin rpy="0 0 0" xyz="0 0 0.05315"/>
    <limit effort="100.0" lower="-2.618" upper="2.618" velocity="1.0"/>
    <axis xyz="0 0 1"/>
  </joint>
  <link name="left_arm_shoulder_roll">
    <visual>
      <origin rpy="1.5708 0 0.384" xyz="0 0 0"/>
      <geometry>
        <mesh filename="package://cyton_gamma_1500_description/meshes/shoulder_roll.dae"/>
      </geometry>
    </visual>
    <collision>
      <origin xyz="0.0 0.069 0.0587"/>
      <geometry>
        <box size="0.09829 0.18143 0.08392"/>
      </geometry>
    </collision>
    <inertial>
      <mass value="50.0"/>
      <origin rpy="0 0 0" xyz="0 0 0"/>
      <inertia ixx=".1027" ixy="0" ixz="0" iyy=".1027" iyz="0" izz=".1027"/>
    </inertial>
  </link>
  <joint name="left_arm_shoulder_pitch_joint" type="revolute">
    <parent link="left_arm_shoulder_roll"/>
    <child link="left_arm_shoulder_pitch"/>
    <origin rpy="0 0 0" xyz="0.0205 0 0.12435"/>
    <limit effort="100.0" lower="-1.8326" upper="1.8326" velocity="1.0"/>
    <axis xyz="1 0 0"/>
  </joint>
  <transmission name="left_arm_tran1">
    <type>transmission_interface/SimpleTransmission</type>
    <joint name="left_arm_shoulder_roll_joint">
      <hardwareInterface>hardware_interface/PositionJointInterface</hardwareInterface>
    </joint>
    <actuator name="left_arm_motor1">
      <hardwareInterface>hardware_interface/PositionJointInterface</hardwareInterface>
    </actuator>
  </transmission>
  <link name="left_arm_shoulder_pitch">
    <visual>
      <origin rpy="1.5708 0 0" xyz="0 0 0"/>
      <geometry>
        <mesh filename="package://cyton_gamma_1500_description/meshes/shoulder_pitch.dae"/>
      </geometry>
    </visual>
    <collision>
      <origin xyz="-0.02 0.0 0.0"/>
      <geometry>
        <sphere radius="0.055"/>
        <!--box size="0.098 0.08 0.11"/-->
      </geometry>
    </collision>
    <inertial>
      <mass value="20.0"/>
      <origin rpy="0 0 0" xyz="0 0 0"/>
      <inertia ixx=".0827" ixy="0" ixz="0" iyy=".0827" iyz="0" izz=".0827"/>
    </inertial>
  </link>
  <joint name="left_arm_shoulder_yaw_joint" type="revolute">
    <parent link="left_arm_shoulder_pitch"/>
    <child link="left_arm_shoulder_yaw"/>
    <origin rpy="0 0 0" xyz="-0.0215 -0.0205 0.1255"/>
    <limit effort="100.0" lower="-1.8326" upper="1.8326" velocity="1.0"/>
    <axis xyz="0 -1 0"/>
  </joint>
  <transmission name="left_arm_tran2">
    <type>transmission_interface/SimpleTransmission</type>
    <joint name="left_arm_shoulder_pitch_joint">
      <hardwareInterface>hardware_interface/PositionJointInterface</hardwareInterface>
    </joint>
    <actuator name="left_arm_motor2">
      <hardwareInterface>hardware_interface/PositionJointInterface</hardwareInterface>
    </actuator>
  </transmission>
  <link name="left_arm_shoulder_yaw">
    <visual>
      <origin rpy="1.5708 0 -1.5708" xyz="0 0 0.0"/>
      <geometry>
        <mesh filename="package://cyton_gamma_1500_description/meshes/shoulder_yaw.dae"/>
      </geometry>
    </visual>
    <collision>
      <origin xyz=" -0.002 0.02 -0.01"/>
      <geometry>
        <sphere radius="0.055"/>
        <!--box size="0.08 0.1 0.11"/-->
      </geometry>
    </collision>
    <inertial>
      <mass value="10.0"/>
      <origin rpy="0 0 0" xyz="0 0 0"/>
      <inertia ixx=".0627" ixy="0" ixz="0" iyy=".0627" iyz="0" izz=".0627"/>
    </inertial>
  </link>
  <transmission name="left_arm_tran3">
    <type>transmission_interface/SimpleTransmission</type>
    <joint name="left_arm_shoulder_yaw_joint">
      <hardwareInterface>hardware_interface/PositionJointInterface</hardwareInterface>
    </joint>
    <actuator name="left_arm_motor3">
      <hardwareInterface>hardware_interface/PositionJointInterface</hardwareInterface>
    </actuator>
  </transmission>
  <joint name="left_arm_elbow_pitch_joint" type="revolute">
    <parent link="left_arm_shoulder_yaw"/>
    <child link="left_arm_elbow_pitch"/>
    <origin rpy="0 0 0" xyz="0.018 0.0206 0.1158"/>
    <limit effort="100.0" lower="-1.8326" upper="1.8326" velocity="1.0"/>
    <axis xyz="1 0 0"/>
  </joint>
  <link name="left_arm_elbow_pitch">
    <visual>
      <origin rpy="1.5708 0 3.1416" xyz="0 0 0"/>
      <geometry>
        <mesh filename="package://cyton_gamma_1500_description/meshes/elbow_pitch.dae"/>
      </geometry>
    </visual>
    <collision>
      <origin xyz="-0.022 0.0 -0.006"/>
      <geometry>
        <sphere radius="0.055"/>
        <!--box size="0.09 0.1 0.11"/-->
      </geometry>
    </collision>
    <inertial>
      <mass value="10.0"/>
      <origin rpy="0 0 0" xyz="0 0 0"/>
      <inertia ixx=".0327" ixy="0" ixz="0" iyy=".0327" iyz="0" izz=".0327"/>
    </inertial>
  </link>
  <transmission name="left_arm_tran4">
    <type>transmission_interface/SimpleTransmission</type>
    <joint name="left_arm_elbow_pitch_joint">
      <hardwareInterface>hardware_interface/PositionJointInterface</hardwareInterface>
    </joint>
    <actuator name="left_arm_motor4">
      <hardwareInterface>hardware_interface/PositionJointInterface</hardwareInterface>
    </actuator>
  </transmission>
  <joint name="left_arm_elbow_yaw_joint" type="revolute">
    <parent link="left_arm_elbow_pitch"/>
    <child link="left_arm_elbow_yaw"/>
    <origin rpy="0 0 0" xyz="-0.0171 -0.018 0.09746"/>
    <limit effort="100.0" lower="-1.8326" upper="1.8326" velocity="1.0"/>
    <axis xyz="0 -1 0"/>
  </joint>
  <link name="left_arm_elbow_yaw">
    <visual>
      <origin rpy="1.5708 0 1.5708" xyz="0 0 0"/>
      <geometry>
        <mesh filename="package://cyton_gamma_1500_description/meshes/elbow_yaw.dae"/>
      </geometry>
    </visual>
    <collision>
      <origin xyz="0.0 0.025 0.0"/>
      <geometry>
        <sphere radius="0.05"/>
      </geometry>
    </collision>
    <inertial>
      <mass value="10.0"/>
      <origin rpy="0 0 0" xyz="0 0 0"/>
      <inertia ixx=".0227" ixy="0" ixz="0" iyy=".0227" iyz="0" izz=".0227"/>
    </inertial>
  </link>
  <transmission name="left_arm_tran5">
    <type>transmission_interface/SimpleTransmission</type>
    <joint name="left_arm_elbow_yaw_joint">
      <hardwareInterface>hardware_interface/PositionJointInterface</hardwareInterface>
    </joint>
    <actuator name="left_arm_motor5">
      <hardwareInterface>hardware_interface/PositionJointInterface</hardwareInterface>
    </actuator>
  </transmission>
  <joint name="left_arm_wrist_pitch_joint" type="revolute">
    <parent link="left_arm_elbow_yaw"/>
    <child link="left_arm_wrist_pitch"/>
    <origin rpy="0 0 0" xyz="0.02626 0.018 0.0718"/>
    <limit effort="100.0" lower="-1.8326" upper="1.8326" velocity="1.0"/>
    <axis xyz="-1 0 0"/>
  </joint>
  <link name="left_arm_wrist_pitch">
    <visual>
      <origin rpy="1.5708 0 1.5708" xyz="0 0 0"/>
      <geometry>
        <mesh filename="package://cyton_gamma_1500_description/meshes/wrist_pitch.dae"/>
      </geometry>
    </visual>
    <collision>
      <origin xyz="-0.02 0.0 0.0"/>
      <geometry>
        <box size="0.07 0.06 0.11"/>
      </geometry>
    </collision>
    <inertial>
      <mass value="10.0"/>
      <origin rpy="0 0 0" xyz="0 0 0"/>
      <inertia ixx=".0127" ixy="0" ixz="0" iyy=".0127" iyz="0" izz=".0127"/>
    </inertial>
  </link>
  <transmission name="left_arm_tran6">
    <type>transmission_interface/SimpleTransmission</type>
    <joint name="left_arm_wrist_pitch_joint">
      <hardwareInterface>hardware_interface/PositionJointInterface</hardwareInterface>
    </joint>
    <actuator name="left_arm_motor6">
      <hardwareInterface>hardware_interface/PositionJointInterface</hardwareInterface>
    </actuator>
  </transmission>
  <joint name="left_arm_wrist_roll_joint" type="revolute">
    <parent link="left_arm_wrist_pitch"/>
    <child link="left_arm_wrist_roll"/>
    <origin rpy="0 0 0" xyz="-0.026255 0 0.051425"/>
    <limit effort="100.0" lower="-2.61799" upper="2.61799" velocity="1.0"/>
    <axis xyz="0 0 1"/>
  </joint>
  <link name="left_arm_wrist_roll">
    <visual>
      <origin rpy="3.1416 0 -1.5708" xyz="0 0 0"/>
      <geometry>
        <mesh filename="package://cyton_gamma_1500_description/meshes/wrist_roll.dae"/>
      </geometry>
    </visual>
    <collision>
      <origin xyz="0.0 0.008 0.04"/>
      <geometry>
        <box size="0.08 0.06 0.08"/>
      </geometry>
    </collision>
    <inertial>
      <mass value="10.0"/>
      <origin rpy="0 0 0" xyz="0 0 0"/>
      <inertia ixx=".0027" ixy="0" ixz="0" iyy=".0027" iyz="0" izz=".0027"/>
    </inertial>
  </link>
  <transmission name="left_arm_tran7">
    <type>transmission_interface/SimpleTransmission</type>
    <joint name="left_arm_wrist_roll_joint">
      <hardwareInterface>hardware_interface/PositionJointInterface</hardwareInterface>
    </joint>
    <actuator name="left_arm_motor7">
      <hardwareInterface>hardware_interface/PositionJointInterface</hardwareInterface>
    </actuator>
  </transmission>
  <joint name="left_arm_gripper_joint" type="prismatic">
    <parent link="left_arm_wrist_roll"/>
    <child link="left_arm_gripper_finger1"/>
    <origin rpy="0 0 0" xyz="-0.01331 0.00485 0.077225"/>
    <limit effort="100.0" lower="-0.008" upper="0.008" velocity="1.0"/>
    <axis xyz="1 0 0"/>
  </joint>
  <link name="left_arm_gripper_finger1">
    <visual>
      <origin rpy="0 0 0" xyz="0 0 0"/>
      <geometry>
        <mesh filename="package://cyton_gamma_1500_description/meshes/gripper_finger1.dae"/>
      </geometry>
    </visual>
    <collision>
      <!--origin xyz="-0.0167 0.0172 0.7254"/-->
      <origin xyz="0.0 0.008 0.04"/>
      <geometry>
        <box size="0.015 0.0229 0.0475"/>
      </geometry>
    </collision>
    <inertial>
      <!--origin rpy="0 0 0" xyz="0.0034 0.0096 0.017"/-->
      <origin rpy="0 0 0" xyz="0 0 0"/>
      <mass value="0.035"/>
      <!-- inretia tensor for solid cuboid: m=0.035, h=0.0323, w=0.01469, d=0.0224 -->
      <inertia ixx="4.5064e-06" ixy="0" ixz="0" iyy="3.6723e-06" iyz="0" izz="2.0929e-06"/>
    </inertial>
  </link>
  <transmission name="left_arm_tran8">
    <type>transmission_interface/SimpleTransmission</type>
    <joint name="left_arm_gripper_joint">
      <hardwareInterface>hardware_interface/PositionJointInterface</hardwareInterface>
    </joint>
    <actuator name="left_arm_motor8">
      <hardwareInterface>hardware_interface/PositionJointInterface</hardwareInterface>
    </actuator>
  </transmission>
  <joint name="left_arm_gripper_joint2" type="prismatic">
    <parent link="left_arm_wrist_roll"/>
    <child link="left_arm_gripper_finger2"/>
    <origin rpy="0 0 0" xyz="0.0098 0.00485 0.077225"/>
    <limit effort="100.0" lower="-0.008" upper="0.008" velocity="1.0"/>
    <mimic joint="left_arm_gripper_joint" multiplier="-1"/>
    <axis xyz="1 0 0"/>
  </joint>
  <link name="left_arm_gripper_finger2">
    <visual>
      <origin rpy="0 0 0" xyz="0 0 0"/>
      <geometry>
        <mesh filename="package://cyton_gamma_1500_description/meshes/gripper_finger2.dae"/>
      </geometry>
    </visual>
    <collision>
      <!--origin xyz="0.0132 0.0172 0.7254"/-->
      <origin xyz="0.0 0.008 0.04"/>
      <geometry>
        <box size="0.015 0.0229 0.0475"/>
      </geometry>
    </collision>
    <inertial>
      <!--origin rpy="0 0 0" xyz="0.0034 0.0096 0.017"/-->
      <origin rpy="0 0 0" xyz="0 0 0"/>
      <mass value="0.035"/>
      <!-- inretia tensor for solid cuboid: m=0.035, h=0.0323, w=0.01469, d=0.0224 -->
      <inertia ixx="4.5064e-06" ixy="0" ixz="0" iyy="3.6723e-06" iyz="0" izz="2.0929e-06"/>
    </inertial>
  </link>
  <transmission name="left_arm_tran9">
    <type>transmission_interface/SimpleTransmission</type>
    <joint name="left_arm_gripper_joint2">
      <hardwareInterface>hardware_interface/PositionJointInterface</hardwareInterface>
    </joint>
    <actuator name="left_arm_motor9">
      <hardwareInterface>hardware_interface/PositionJointInterface</hardwareInterface>
    </actuator>
  </transmission>
  <!-- virtual end-effector -->
  <joint name="left_arm_virtual_endeffector_joint" type="fixed">
    <parent link="left_arm_wrist_roll"/>
    <child link="left_arm_virtual_endeffector"/>
    <origin rpy="0 0 0" xyz="-0.002316 0.0079 0.079425"/>
  </joint>
  <link name="left_arm_virtual_endeffector">
    <visual>
      <origin rpy="0 0 0" xyz="0 0 0"/>
      <geometry>
        <sphere radius="0.002"/>
      </geometry>
      <material name="grey">
        <color rgba="0.7 0.7 0.7 0.8"/>
      </material>
    </visual>
  </link>
  <joint name="wheel_left_joint" type="continuous">
    <parent link="fixed_base"/>
    <child link="wheel_left"/>
    <origin rpy="1.570796 0 0" xyz="0.0 0.18 0.095"/>
    <axis xyz="0 0 1"/>
  </joint>
  <link name="wheel_left">
    <inertial>
      <origin rpy="0 0 0" xyz="0.0 0 0"/>
      <mass value="0.5"/>
      <!-- inretia tensor for solid cylinder: m=0.5, h=0.05, r=0.095 -->
      <inertia ixx="1.232291667e-03" ixy="0" ixz="0" iyy="1.232291667e-03" iyz="0" izz="2.25625e-03"/>
    </inertial>
    <visual>
      <origin rpy="0 0 0" xyz="0 0 0"/>
      <geometry>
        <cylinder length="0.05" radius="0.095"/>
      </geometry>
      <material name="blackish">
        <color rgba="0.2 0.2 0.2 1"/>
      </material>
    </visual>
    <collision>
      <origin rpy="0 0 0" xyz="0 0 0"/>
      <geometry>
        <cylinder length="0.05" radius="0.095"/>
      </geometry>
    </collision>
  </link>
  <joint name="wheel_right_joint" type="continuous">
    <parent link="fixed_base"/>
    <child link="wheel_right"/>
    <origin rpy="1.570796 0 0" xyz="0.0 -0.18 0.095"/>
    <axis xyz="0 0 1"/>
  </joint>
  <link name="wheel_right">
    <inertial>
      <origin rpy="0 0 0" xyz="0.0 0 0"/>
      <mass value="0.5"/>
      <!-- inretia tensor for solid cylinder: m=0.5, h=0.05, r=0.095 -->
      <inertia ixx="1.232291667e-03" ixy="0" ixz="0" iyy="1.232291667e-03" iyz="0" izz="2.25625e-03"/>
    </inertial>
    <visual>
      <origin rpy="0 0 0" xyz="0 0 0"/>
      <geometry>
        <cylinder length="0.05" radius="0.095"/>
      </geometry>
      <material name="blackish"/>
    </visual>
    <collision>
      <origin rpy="0 0 0" xyz="0 0 0"/>
      <geometry>
        <cylinder length="0.05" radius="0.095"/>
      </geometry>
    </collision>
  </link>
</robot>
