<?xml version="1.0" ?>
<!-- =================================================================================== -->
<!-- |    This document was autogenerated by xacro from /home/bot/catkin_ws/src/phoebe_stack/phoebe_description/phoebe.urdf.xacro | -->
<!-- |    EDITING THIS FILE BY HAND IS NOT RECOMMENDED                                 | -->
<!-- =================================================================================== -->
<robot name="phoebe" xmlns:xacro="http://www.ros.org/wiki/xacro">
  
  <link name="base_link">
    <inertial>
      <origin rpy="0 0 0" xyz="-0.04 0 0.56"/>
      <mass value="12"/>
      <!-- inretia tensor for solid cuboid: m=12, h=1.12, d=0.49, w=0.41 -->
      <inertia ixx="1.4225" ixy="0" ixz="0" iyy="1.4945" iyz="0" izz="0.4082"/>
    </inertial>
    <visual>
      <origin rpy="0 0 0" xyz="0 0 0"/>
      <geometry>
        <mesh filename="package://phoebe_description/meshes/phoebe.dae"/>
      </geometry>
    </visual>
    <collision>
      <origin rpy="0 0 0" xyz="0 0 0"/>
      <geometry>
        <mesh filename="package://phoebe_description/meshes/phoebe.dae"/>
      </geometry>
    </collision>
  </link>

  <joint name="wheel_left_joint" type="continuous">
    <parent link="base_link"/>
    <child link="wheel_left"/>
    <origin rpy="1.570796 0 0" xyz="0.0 0.18 0.095"/>
    <axis xyz="0 0 1"/>
  </joint>
  <link name="wheel_left">
    <inertial>
      <origin rpy="0 0 0" xyz="0.0 0 0"/>
      <mass value="0.5"/>
      <!-- inretia tensor for solid cylinder: m=0.5, h=0.05, r=0.095 -->
      <inertia ixx="1.232291667e-03" ixy="0" ixz="0" iyy="1.232291667e-03" iyz="0" izz="2.25625e-03"/>
    </inertial>
    <visual>
      <origin rpy="0 0 0" xyz="0 0 0"/>
      <geometry>
        <cylinder length="0.05" radius="0.095"/>
      </geometry>
      <material name="blackish">
        <color rgba="0.2 0.2 0.2 1"/>
      </material>
    </visual>
    <collision>
      <origin rpy="0 0 0" xyz="0 0 0"/>
      <geometry>
        <cylinder length="0.05" radius="0.095"/>
      </geometry>
    </collision>
  </link>
  
  <joint name="wheel_right_joint" type="continuous">
    <parent link="base_link"/>
    <child link="wheel_right"/>
    <origin rpy="1.570796 0 0" xyz="0.0 -0.18 0.095"/>
    <axis xyz="0 0 1"/>
  </joint>
  <link name="wheel_right">
    <inertial>
      <origin rpy="0 0 0" xyz="0.0 0 0"/>
      <mass value="0.5"/>
      <!-- inretia tensor for solid cylinder: m=0.5, h=0.05, r=0.095 -->
      <inertia ixx="1.232291667e-03" ixy="0" ixz="0" iyy="1.232291667e-03" iyz="0" izz="2.25625e-03"/>
    </inertial>
    <visual>
      <origin rpy="0 0 0" xyz="0 0 0"/>
      <geometry>
        <cylinder length="0.05" radius="0.095"/>
      </geometry>
      <material name="blackish"/>
    </visual>
    <collision>
      <origin rpy="0 0 0" xyz="0 0 0"/>
      <geometry>
        <cylinder length="0.05" radius="0.095"/>
      </geometry>
    </collision>
  </link>

  <!-- Cyton Gamma 1500 models -->

  <!-- Right arm -->
	
  <joint name="right_arm_joint" type="fixed">
    <parent link="base_link"/>
    <child link="right_arm_base_link"/>
    <origin rpy="1.5708 -1.5708 0" xyz="0.067 -0.162 0.8"/>
  </joint>
  <link name="right_arm_base_link">
    <inertial>
      <origin rpy="0 0 0" xyz="0.0 0 0"/>
      <mass value="0.478571"/>
      <!-- inretia tensor for solid cuboid: m=0.478571, w=0.177, h=0.074, d=0.150 -->
      <inertia ixx="1.47e-03" ixy="0" ixz="0" iyy="2.15e-03" iyz="0" izz="1.12e-03"/>
    </inertial>
    <visual>
      <origin rpy="0 0 0" xyz="0 0 0"/>
      <geometry>
        <mesh filename="package://cyton_gamma_1500_description/meshes/base.dae"/>
      </geometry>
    </visual>
    <collision>
      <origin xyz="0 0.0115 0.047"/>
      <geometry>
        <box size="0.154 0.177 0.094"/>
      </geometry>
    </collision>
  </link>

  <joint name="right_arm_shoulder_roll_joint" type="revolute">
    <parent link="right_arm_base_link"/>
    <child link="right_arm_shoulder_roll"/>
    <origin rpy="0 0 0" xyz="0 0 0.05315"/>
    <limit effort="100.0" lower="-2.618" upper="2.618" velocity="1.0"/>
    <axis xyz="0 0 1"/>
  </joint>
  <link name="right_arm_shoulder_roll">
    <inertial>
      <origin rpy="0 0 0" xyz="0 0 0.12"/>
      <mass value="0.468571"/>
      <!-- inretia tensor for solid cylinder: m=0.468571, h=0.09248, r=0.044737 -->
      <inertia ixx="4.7e-04" ixy="0" ixz="0" iyy="5.7e-04" iyz="0" izz="5.7e-04"/>
    </inertial>
    <visual>
      <origin rpy="1.5708 0 0.384" xyz="0 0 0"/>
      <geometry>
        <mesh filename="package://cyton_gamma_1500_description/meshes/shoulder_roll.dae"/>
      </geometry>
    </visual>
    <collision>
      <origin xyz="0.0 0.069 0.0587"/>
      <geometry>
        <box size="0.09829 0.18143 0.08392"/>
      </geometry>
    </collision>
  </link>

  <joint name="right_arm_shoulder_pitch_joint" type="revolute">
    <parent link="right_arm_shoulder_roll"/>
    <child link="right_arm_shoulder_pitch"/>
    <origin rpy="0 0 0" xyz="0.0205 0 0.12435"/>
    <limit effort="100.0" lower="-1.8326" upper="1.8326" velocity="1.0"/>
    <axis xyz="1 0 0"/>
  </joint>
  <link name="right_arm_shoulder_pitch">
    <inertial>
      <origin rpy="0 0 0" xyz="-0.0214 0 0.117"/>
      <mass value="0.4285714"/>
      <!-- inretia tensor for solid cylinder: m=0.4285714, h=0.09248, r=0.04204 -->
      <inertia ixx="4.9e-04" ixy="0" ixz="0" iyy="3.8e-04" iyz="0" izz="4.9e-04"/>
    </inertial>
    <visual>
      <origin rpy="1.5708 0 0" xyz="0 0 0"/>
      <geometry>
        <mesh filename="package://cyton_gamma_1500_description/meshes/shoulder_pitch.dae"/>
      </geometry>
    </visual>
    <collision>
      <origin xyz="-0.001 0.064 0.1745"/>
      <geometry>
        <box size="0.0709 0.19363 0.083"/>
      </geometry>
    </collision>
  </link>

  <joint name="right_arm_shoulder_yaw_joint" type="revolute">
    <parent link="right_arm_shoulder_pitch"/>
    <child link="right_arm_shoulder_yaw"/>
    <origin rpy="0 0 0" xyz="-0.0215 -0.0205 0.1255"/>
    <limit effort="100.0" lower="-1.8326" upper="1.8326" velocity="1.0"/>
    <axis xyz="0 -1 0"/>
  </joint>
  <link name="right_arm_shoulder_yaw">
    <inertial>
      <origin rpy="0 0 0" xyz="-0.002 0.021 0.1135"/>
      <mass value="0.408571"/>
      <!-- inretia tensor for solid cylinder: m=0.408571, h=0.084081, r=0.036785 -->
      <inertia ixx="2.8e-04" ixy="0" ixz="0" iyy="3.8e-04" iyz="0" izz="3.8e-04"/>
    </inertial>
    <visual>
      <origin rpy="1.5708 0 -1.5708" xyz="0 0 0.0"/>
      <geometry>
        <mesh filename="package://cyton_gamma_1500_description/meshes/shoulder_yaw.dae"/>
      </geometry>
    </visual>
    <collision>
      <origin xyz="-0.0225 0.039 0.3068"/>
      <geometry>
        <box size="0.0717 0.1846 0.0756"/>
      </geometry>
    </collision>
  </link>

  <joint name="right_arm_elbow_pitch_joint" type="revolute">
    <parent link="right_arm_shoulder_yaw"/>
    <child link="right_arm_elbow_pitch"/>
    <origin rpy="0 0 0" xyz="0.018 0.0206 0.1158"/>
    <limit effort="100.0" lower="-1.8326" upper="1.8326" velocity="1.0"/>
    <axis xyz="1 0 0"/>
  </joint>
  <link name="right_arm_elbow_pitch">
    <inertial>
      <origin rpy="0 0 0" xyz="-0.0176 0.001 0.095"/>
      <mass value="0.388671"/>
      <!-- inretia tensor for solid cylinder: m=0.388671, h=0.06705, r=0.028975 -->
      <inertia ixx="2.3e-04" ixy="0" ixz="0" iyy="1.6e-04" iyz="0" izz="2.3e-04"/>
    </inertial>
    <visual>
      <origin rpy="1.5708 0 3.1416" xyz="0 0 0"/>
      <geometry>
        <mesh filename="package://cyton_gamma_1500_description/meshes/elbow_pitch.dae"/>
      </geometry>
    </visual>
    <collision>
      <origin xyz="0.0346 0.0461 0.4228"/>
      <geometry>
        <box size="0.0549 0.1557 0.076"/>
      </geometry>
    </collision>
  </link>

  <joint name="right_arm_elbow_yaw_joint" type="revolute">
    <parent link="right_arm_elbow_pitch"/>
    <child link="right_arm_elbow_yaw"/>
    <origin rpy="0 0 0" xyz="-0.0171 -0.018 0.09746"/>
    <limit effort="100.0" lower="-1.8326" upper="1.8326" velocity="1.0"/>
    <axis xyz="0 -1 0"/>
  </joint>
  <link name="right_arm_elbow_yaw">
    <inertial>
      <origin rpy="0 0 0" xyz="0 0.018 0.073"/>
      <mass value="0.368871"/>
      <!-- inretia tensor for solid cylinder: m=0.368871, h=0.043602, r=0.024071 -->
      <inertia ixx="1.0686e-04" ixy="0" ixz="0" iyy="1.1187e-04" iyz="0" izz="1.1187e-04"/>
    </inertial>
    <visual>
      <origin rpy="1.5708 0 1.5708" xyz="0 0 0"/>
      <geometry>
        <mesh filename="package://cyton_gamma_1500_description/meshes/elbow_yaw.dae"/>
      </geometry>
    </visual>
    <collision>
      <origin xyz="0.0172 0.0209 0.516"/>
      <geometry>
        <box size="0.0535 0.1160 0.0402"/>
      </geometry>
    </collision>
  </link>

  <joint name="right_arm_wrist_pitch_joint" type="revolute">
    <parent link="right_arm_elbow_yaw"/>
    <child link="right_arm_wrist_pitch"/>
    <origin rpy="0 0 0" xyz="0.02626 0.018 0.0718"/>
    <limit effort="100.0" lower="-1.8326" upper="1.8326" velocity="1.0"/>
    <axis xyz="-1 0 0"/>
  </joint>
  <link name="right_arm_wrist_pitch">
    <inertial>
      <origin rpy="0 0 0" xyz="-0.027 -0.0005 0.028"/>
      <mass value="0.008"/>
      <!-- inretia tensor for solid cuboid: m=0.008, h=0.045602, w=0.0218, d=0.005 -->
      <inertia ixx="3.3349e-07" ixy="0" ixz="0" iyy="1.403e-06" iyz="0" izz="1.70319e-06"/>
    </inertial>
    <visual>
      <origin rpy="1.5708 0 1.5708" xyz="0 0 0"/>
      <geometry>
        <mesh filename="package://cyton_gamma_1500_description/meshes/wrist_pitch.dae"/>
      </geometry>
    </visual>
    <collision>
      <origin xyz="0.0257 0.0118 0.5617"/>
      <geometry>
        <box size="0.026 0.0435 0.05185"/>
      </geometry>
    </collision>
  </link>  

  <joint name="right_arm_wrist_roll_joint" type="revolute">
    <parent link="right_arm_wrist_pitch"/>
    <child link="right_arm_wrist_roll"/>
    <origin rpy="0 0 0" xyz="-0.026255 0 0.051425"/>
    <limit effort="100.0" lower="-2.61799" upper="2.61799" velocity="1.0"/>
    <axis xyz="0 0 1"/>
  </joint>
  <link name="right_arm_wrist_roll">
    <inertial>
      <origin rpy="0 0 0" xyz="0 0 0.029"/>
      <mass value="0.38"/>
      <!-- inretia tensor for solid cylinder: m=0.38, h=0.095, r=0.027975 -->
      <inertia ixx="3.6e-04" ixy="0" ixz="0" iyy="3.6e-04" iyz="0" izz="1.487e-04"/>
    </inertial>
    <visual>
      <origin rpy="3.1416 0 -1.5708" xyz="0 0 0"/>
      <geometry>
        <mesh filename="package://cyton_gamma_1500_description/meshes/wrist_roll.dae"/>
      </geometry>
    </visual>
    <collision>
      <origin xyz="-0.0063 -0.0014 0.6102"/>
      <geometry>
        <box size="0.0518 0.0723 0.1004"/>
      </geometry>
    </collision>
  </link>

  <joint name="right_arm_gripper_joint" type="prismatic">
    <parent link="right_arm_wrist_roll"/>
    <child link="right_arm_gripper_finger1"/>
    <origin rpy="0 0 0" xyz="-0.01331 0.00485 0.077225"/>
    <limit effort="100.0" lower="-0.008" upper="0.008" velocity="1.0"/>
    <axis xyz="1 0 0"/>
  </joint>
  <link name="right_arm_gripper_finger1">
    <inertial>
      <origin rpy="0 0 0" xyz="-0.0036 0.0096 0.017"/>
      <mass value="0.035"/>
      <!-- inretia tensor for solid cuboid: m=0.035, h=0.0323, w=0.01469, d=0.0224 -->
      <inertia ixx="4.5064e-06" ixy="0" ixz="0" iyy="3.6723e-06" iyz="0" izz="2.0929e-06"/>
    </inertial>
    <visual>
      <origin rpy="0 0 0" xyz="0 0 0"/>
      <geometry>
        <mesh filename="package://cyton_gamma_1500_description/meshes/gripper_finger1.dae"/>
      </geometry>
    </visual>
    <collision>
      <origin xyz="-0.0167 0.0172 0.7254"/>
      <geometry>
        <box size="0.015 0.0229 0.0475"/>
      </geometry>
    </collision>
  </link>

  <joint name="right_arm_gripper_joint2" type="prismatic">
    <parent link="right_arm_wrist_roll"/>
    <child link="right_arm_gripper_finger2"/>
    <origin rpy="0 0 0" xyz="0.0098 0.00485 0.077225"/>
    <limit effort="100.0" lower="-0.008" upper="0.008" velocity="1.0"/>
    <mimic joint="right_arm_gripper_joint" multiplier="-1"/>
    <axis xyz="1 0 0"/>
  </joint>
  <link name="right_arm_gripper_finger2">
    <inertial>
      <origin rpy="0 0 0" xyz="0.0034 0.0096 0.017"/>
      <mass value="0.035"/>
      <!-- inretia tensor for solid cuboid: m=0.035, h=0.0323, w=0.01469, d=0.0224 -->
      <inertia ixx="4.5064e-06" ixy="0" ixz="0" iyy="3.6723e-06" iyz="0" izz="2.0929e-06"/>
    </inertial>
    <visual>
      <origin rpy="0 0 0" xyz="0 0 0"/>
      <geometry>
        <mesh filename="package://cyton_gamma_1500_description/meshes/gripper_finger2.dae"/>
      </geometry>
    </visual>
    <collision>
      <origin xyz="0.0132 0.0172 0.7254"/>
      <geometry>
        <box size="0.015 0.0229 0.0475"/>
      </geometry>
    </collision>
  </link>

  <!-- virtual end-effector -->

  <joint name="right_arm_virtual_endeffector_joint" type="fixed">
    <parent link="right_arm_wrist_roll"/>
    <child link="right_arm_virtual_endeffector"/>
    <origin rpy="0 0 0" xyz="-0.002316 0.0079 0.079425"/>
  </joint>
  <link name="right_arm_virtual_endeffector">
    <inertial>
      <origin rpy="0 0 0" xyz="0 0 0"/>
      <mass value="0.0016"/>
      <!-- inretia tensor for solid sphere: m=0.0016, r=0.0022 -->
      <inertia ixx="3.0976e-09" ixy="0" ixz="0" iyy="3.0976e-09" iyz="0" izz="3.0976e-09"/>
    </inertial>
    <visual>
      <origin rpy="0 0 0" xyz="0 0 0"/>
      <geometry>
        <sphere radius="0.002"/>
      </geometry>
      <material name="grey">
        <color rgba="0.7 0.7 0.7 0.8"/>
      </material>
    </visual>
  </link>

  <joint name="right_arm_camera_bracket_joint" type="fixed">
    <parent link="right_arm_wrist_roll"/>
    <child link="right_arm_camera_bracket"/>
    <origin rpy="0 0 0" xyz="-0.0008 -0.028 0.0435"/>
  </joint>
  <link name="right_arm_camera_bracket">
    <inertial>
      <origin rpy="0.95 0 0" xyz="0 -0.01 -0.012"/>
      <mass value="0.052"/>
      <!-- inretia tensor for solid cuboid: m=0.052, h=0.071, w=0.028, d=0.0086 -->
      <inertia ixx="2.2165e-05" ixy="0" ixz="0" iyy="3.7178e-06" iyz="0" izz="2.5242e-05"/>
    </inertial>
    <visual>
      <origin rpy="0 0 0" xyz="0 0 0"/>
      <geometry>
        <mesh filename="package://cyton_gamma_1500_minicam_description/meshes/cam_bracket.dae"/>
      </geometry>
    </visual>
    <!--collision>
        <origin xyz="0.0 0.0 0.0"/>
        <geometry>
          <box size="0.03512 0.04821 0.07179"/>
        </geometry>
      </collision-->
  </link>

  <joint name="right_arm_camera_joint" type="fixed">
    <parent link="right_arm_camera_bracket"/>
    <child link="right_arm_camera"/>
    <origin rpy="-0.625 0 0" xyz="0.0 -0.028 -0.005"/>
  </joint>
  <link name="right_arm_camera">
    <inertial>
      <origin rpy="0 0 0" xyz="0 0 0"/>
      <mass value="0.085"/>
      <!-- inretia tensor for solid cuboid: m=0.085, h=0.065, w=0.024, d=0.024 -->
      <inertia ixx="3.4007e-05" ixy="0" ixz="0" iyy="3.4007e-05" iyz="0" izz="8.16e-06"/>
    </inertial>
    <visual>
      <origin rpy="0 0 0" xyz="0 0 0"/>
      <geometry>
        <box size="0.031 0.028 0.063"/>
      </geometry>
      <material name="blackish">
        <color rgba="0.2 0.2 0.2 1"/>
      </material>
    </visual>
    <collision>
      <origin rpy="0 0 0" xyz="0 0 0"/>
      <geometry>
        <box size="0.036 0.045 0.063"/>
      </geometry>
    </collision>
  </link>

  <!-- Left arm -->

  <joint name="left_arm_joint" type="fixed">
    <parent link="base_link"/>
    <child link="left_arm_base_link"/>
    <origin rpy="-1.5708 1.5708 0" xyz="0.067 0.162 0.8"/>
  </joint>
  <link name="left_arm_base_link">
    <inertial>
      <origin rpy="0 0 0" xyz="0.0 0 0"/>
      <mass value="0.478571"/>
      <!-- inretia tensor for solid cuboid: m=0.478571, w=0.177, h=0.074, d=0.150 -->
      <inertia ixx="1.47e-03" ixy="0" ixz="0" iyy="2.15e-03" iyz="0" izz="1.12e-03"/>
    </inertial>
    <visual>
      <origin rpy="0 0 0" xyz="0 0 0"/>
      <geometry>
        <mesh filename="package://cyton_gamma_1500_description/meshes/base.dae"/>
      </geometry>
    </visual>
    <collision>
      <origin xyz="0 0.0115 0.047"/>
      <geometry>
        <box size="0.154 0.177 0.094"/>
      </geometry>
    </collision>
  </link>

  <joint name="left_arm_shoulder_roll_joint" type="revolute">
    <parent link="left_arm_base_link"/>
    <child link="left_arm_shoulder_roll"/>
    <origin rpy="0 0 0" xyz="0 0 0.05315"/>
    <limit effort="100.0" lower="-2.618" upper="2.618" velocity="1.0"/>
    <axis xyz="0 0 1"/>
  </joint>
  <link name="left_arm_shoulder_roll">
    <inertial>
      <origin rpy="0 0 0" xyz="0 0 0.12"/>
      <mass value="0.468571"/>
      <!-- inretia tensor for solid cylinder: m=0.468571, h=0.09248, r=0.044737 -->
      <inertia ixx="4.7e-04" ixy="0" ixz="0" iyy="5.7e-04" iyz="0" izz="5.7e-04"/>
    </inertial>
    <visual>
      <origin rpy="1.5708 0 0.384" xyz="0 0 0"/>
      <geometry>
        <mesh filename="package://cyton_gamma_1500_description/meshes/shoulder_roll.dae"/>
      </geometry>
    </visual>
    <collision>
      <origin xyz="0.0 0.069 0.0587"/>
      <geometry>
        <box size="0.09829 0.18143 0.08392"/>
      </geometry>
    </collision>
  </link> 

  <joint name="left_arm_shoulder_pitch_joint" type="revolute">
    <parent link="left_arm_shoulder_roll"/>
    <child link="left_arm_shoulder_pitch"/>
    <origin rpy="0 0 0" xyz="0.0205 0 0.12435"/>
    <limit effort="100.0" lower="-1.8326" upper="1.8326" velocity="1.0"/>
    <axis xyz="1 0 0"/>
  </joint>
  <link name="left_arm_shoulder_pitch">
    <inertial>
      <origin rpy="0 0 0" xyz="-0.0214 0 0.117"/>
      <mass value="0.4285714"/>
      <!-- inretia tensor for solid cylinder: m=0.4285714, h=0.09248, r=0.04204 -->
      <inertia ixx="4.9e-04" ixy="0" ixz="0" iyy="3.8e-04" iyz="0" izz="4.9e-04"/>
    </inertial>
    <visual>
      <origin rpy="1.5708 0 0" xyz="0 0 0"/>
      <geometry>
        <mesh filename="package://cyton_gamma_1500_description/meshes/shoulder_pitch.dae"/>
      </geometry>
    </visual>
    <collision>
      <origin xyz="-0.001 0.064 0.1745"/>
      <geometry>
        <box size="0.0709 0.19363 0.083"/>
      </geometry>
    </collision>
  </link>

  <joint name="left_arm_shoulder_yaw_joint" type="revolute">
    <parent link="left_arm_shoulder_pitch"/>
    <child link="left_arm_shoulder_yaw"/>
    <origin rpy="0 0 0" xyz="-0.0215 -0.0205 0.1255"/>
    <limit effort="100.0" lower="-1.8326" upper="1.8326" velocity="1.0"/>
    <axis xyz="0 -1 0"/>
  </joint>
  <link name="left_arm_shoulder_yaw">
    <inertial>
      <origin rpy="0 0 0" xyz="-0.002 0.021 0.1135"/>
      <mass value="0.408571"/>
      <!-- inretia tensor for solid cylinder: m=0.408571, h=0.084081, r=0.036785 -->
      <inertia ixx="2.8e-04" ixy="0" ixz="0" iyy="3.8e-04" iyz="0" izz="3.8e-04"/>
    </inertial>
    <visual>
      <origin rpy="1.5708 0 -1.5708" xyz="0 0 0.0"/>
      <geometry>
        <mesh filename="package://cyton_gamma_1500_description/meshes/shoulder_yaw.dae"/>
      </geometry>
    </visual>
    <collision>
      <origin xyz="-0.0225 0.039 0.3068"/>
      <geometry>
        <box size="0.0717 0.1846 0.0756"/>
      </geometry>
    </collision>
  </link>

  <joint name="left_arm_elbow_pitch_joint" type="revolute">
    <parent link="left_arm_shoulder_yaw"/>
    <child link="left_arm_elbow_pitch"/>
    <origin rpy="0 0 0" xyz="0.018 0.0206 0.1158"/>
    <limit effort="100.0" lower="-1.8326" upper="1.8326" velocity="1.0"/>
    <axis xyz="1 0 0"/>
  </joint>
  <link name="left_arm_elbow_pitch">
    <inertial>
      <origin rpy="0 0 0" xyz="-0.0176 0.001 0.095"/>
      <mass value="0.388671"/>
      <!-- inretia tensor for solid cylinder: m=0.388671, h=0.06705, r=0.028975 -->
      <inertia ixx="2.3e-04" ixy="0" ixz="0" iyy="1.6e-04" iyz="0" izz="2.3e-04"/>
    </inertial>
    <visual>
      <origin rpy="1.5708 0 3.1416" xyz="0 0 0"/>
      <geometry>
        <mesh filename="package://cyton_gamma_1500_description/meshes/elbow_pitch.dae"/>
      </geometry>
    </visual>
    <collision>
      <origin xyz="0.0346 0.0461 0.4228"/>
      <geometry>
        <box size="0.0549 0.1557 0.076"/>
      </geometry>
    </collision>
  </link>

  <joint name="left_arm_elbow_yaw_joint" type="revolute">
    <parent link="left_arm_elbow_pitch"/>
    <child link="left_arm_elbow_yaw"/>
    <origin rpy="0 0 0" xyz="-0.0171 -0.018 0.09746"/>
    <limit effort="100.0" lower="-1.8326" upper="1.8326" velocity="1.0"/>
    <axis xyz="0 -1 0"/>
  </joint>
  <link name="left_arm_elbow_yaw">
    <inertial>
      <origin rpy="0 0 0" xyz="0 0.018 0.073"/>
      <mass value="0.368871"/>
      <!-- inretia tensor for solid cylinder: m=0.368871, h=0.043602, r=0.024071 -->
      <inertia ixx="1.0686e-04" ixy="0" ixz="0" iyy="1.1187e-04" iyz="0" izz="1.1187e-04"/>
    </inertial>
    <visual>
      <origin rpy="1.5708 0 1.5708" xyz="0 0 0"/>
      <geometry>
        <mesh filename="package://cyton_gamma_1500_description/meshes/elbow_yaw.dae"/>
      </geometry>
    </visual>
    <collision>
      <origin xyz="0.0172 0.0209 0.516"/>
      <geometry>
        <box size="0.0535 0.1160 0.0402"/>
      </geometry>
    </collision>
  </link>

  <joint name="left_arm_wrist_pitch_joint" type="revolute">
    <parent link="left_arm_elbow_yaw"/>
    <child link="left_arm_wrist_pitch"/>
    <origin rpy="0 0 0" xyz="0.02626 0.018 0.0718"/>
    <limit effort="100.0" lower="-1.8326" upper="1.8326" velocity="1.0"/>
    <axis xyz="-1 0 0"/>
  </joint>
  <link name="left_arm_wrist_pitch">
    <inertial>
      <origin rpy="0 0 0" xyz="-0.027 -0.0005 0.028"/>
      <mass value="0.008"/>
      <!-- inretia tensor for solid cuboid: m=0.008, h=0.045602, w=0.0218, d=0.005 -->
      <inertia ixx="3.3349e-07" ixy="0" ixz="0" iyy="1.403e-06" iyz="0" izz="1.70319e-06"/>
    </inertial>
    <visual>
      <origin rpy="1.5708 0 1.5708" xyz="0 0 0"/>
      <geometry>
        <mesh filename="package://cyton_gamma_1500_description/meshes/wrist_pitch.dae"/>
      </geometry>
    </visual>
    <collision>
      <origin xyz="0.0257 0.0118 0.5617"/>
      <geometry>
        <box size="0.026 0.0435 0.05185"/>
      </geometry>
    </collision>
  </link>

  <joint name="left_arm_wrist_roll_joint" type="revolute">
    <parent link="left_arm_wrist_pitch"/>
    <child link="left_arm_wrist_roll"/>
    <origin rpy="0 0 0" xyz="-0.026255 0 0.051425"/>
    <limit effort="100.0" lower="-2.61799" upper="2.61799" velocity="1.0"/>
    <axis xyz="0 0 1"/>
  </joint>
  <link name="left_arm_wrist_roll">
    <inertial>
      <origin rpy="0 0 0" xyz="0 0 0.029"/>
      <mass value="0.38"/>
      <!-- inretia tensor for solid cylinder: m=0.38, h=0.095, r=0.027975 -->
      <inertia ixx="3.6e-04" ixy="0" ixz="0" iyy="3.6e-04" iyz="0" izz="1.487e-04"/>
    </inertial>
    <visual>
      <origin rpy="3.1416 0 -1.5708" xyz="0 0 0"/>
      <geometry>
        <mesh filename="package://cyton_gamma_1500_description/meshes/wrist_roll.dae"/>
      </geometry>
    </visual>
    <collision>
      <origin xyz="-0.0063 -0.0014 0.6102"/>
      <geometry>
        <box size="0.0518 0.0723 0.1004"/>
      </geometry>
    </collision>
  </link>

  <joint name="left_arm_gripper_joint" type="prismatic">
    <parent link="left_arm_wrist_roll"/>
    <child link="left_arm_gripper_finger1"/>
    <origin rpy="0 0 0" xyz="-0.01331 0.00485 0.077225"/>
    <limit effort="100.0" lower="-0.008" upper="0.008" velocity="1.0"/>
    <axis xyz="1 0 0"/>
  </joint>
  <link name="left_arm_gripper_finger1">
    <inertial>
      <origin rpy="0 0 0" xyz="-0.0036 0.0096 0.017"/>
      <mass value="0.035"/>
      <!-- inretia tensor for solid cuboid: m=0.035, h=0.0323, w=0.01469, d=0.0224 -->
      <inertia ixx="4.5064e-06" ixy="0" ixz="0" iyy="3.6723e-06" iyz="0" izz="2.0929e-06"/>
    </inertial>
    <visual>
      <origin rpy="0 0 0" xyz="0 0 0"/>
      <geometry>
        <mesh filename="package://cyton_gamma_1500_description/meshes/gripper_finger1.dae"/>
      </geometry>
    </visual>
    <collision>
      <origin xyz="-0.0167 0.0172 0.7254"/>
      <geometry>
        <box size="0.015 0.0229 0.0475"/>
      </geometry>
    </collision>
  </link>

  <joint name="left_arm_gripper_joint2" type="prismatic">
    <parent link="left_arm_wrist_roll"/>
    <child link="left_arm_gripper_finger2"/>
    <origin rpy="0 0 0" xyz="0.0098 0.00485 0.077225"/>
    <limit effort="100.0" lower="-0.008" upper="0.008" velocity="1.0"/>
    <mimic joint="left_arm_gripper_joint" multiplier="-1"/>
    <axis xyz="1 0 0"/>
  </joint>
  <link name="left_arm_gripper_finger2">
    <inertial>
      <origin rpy="0 0 0" xyz="0.0034 0.0096 0.017"/>
      <mass value="0.035"/>
      <!-- inretia tensor for solid cuboid: m=0.035, h=0.0323, w=0.01469, d=0.0224 -->
      <inertia ixx="4.5064e-06" ixy="0" ixz="0" iyy="3.6723e-06" iyz="0" izz="2.0929e-06"/>
    </inertial>
    <visual>
      <origin rpy="0 0 0" xyz="0 0 0"/>
      <geometry>
        <mesh filename="package://cyton_gamma_1500_description/meshes/gripper_finger2.dae"/>
      </geometry>
    </visual>
    <collision>
      <origin xyz="0.0132 0.0172 0.7254"/>
      <geometry>
        <box size="0.015 0.0229 0.0475"/>
      </geometry>
    </collision>
  </link>

  <!-- virtual end-effector -->

  <joint name="left_arm_virtual_endeffector_joint" type="fixed">
    <parent link="left_arm_wrist_roll"/>
    <child link="left_arm_virtual_endeffector"/>
    <origin rpy="0 0 0" xyz="-0.002316 0.0079 0.079425"/>
  </joint>
  <link name="left_arm_virtual_endeffector">
    <inertial>
      <origin rpy="0 0 0" xyz="0 0 0"/>
      <mass value="0.0016"/>
      <!-- inretia tensor for solid sphere: m=0.0016, r=0.0022 -->
      <inertia ixx="3.0976e-09" ixy="0" ixz="0" iyy="3.0976e-09" iyz="0" izz="3.0976e-09"/>
    </inertial>
    <visual>
      <origin rpy="0 0 0" xyz="0 0 0"/>
      <geometry>
        <sphere radius="0.002"/>
      </geometry>
      <material name="grey">
        <color rgba="0.7 0.7 0.7 0.8"/>
      </material>
    </visual>
  </link>

  <joint name="left_arm_camera_bracket_joint" type="fixed">
    <parent link="left_arm_wrist_roll"/>
    <child link="left_arm_camera_bracket"/>
    <origin rpy="0 0 0" xyz="-0.0008 -0.028 0.0435"/>
  </joint>
  <link name="left_arm_camera_bracket">
    <inertial>
      <origin rpy="0.95 0 0" xyz="0 -0.01 -0.012"/>
      <mass value="0.052"/>
      <!-- inretia tensor for solid cuboid: m=0.052, h=0.071, w=0.028, d=0.0086 -->
      <inertia ixx="2.2165e-05" ixy="0" ixz="0" iyy="3.7178e-06" iyz="0" izz="2.5242e-05"/>
    </inertial>
    <visual>
      <origin rpy="0 0 0" xyz="0 0 0"/>
      <geometry>
        <mesh filename="package://cyton_gamma_1500_minicam_description/meshes/cam_bracket.dae"/>
      </geometry>
    </visual>
    <!--collision>
        <origin xyz="0.0 0.0 0.0"/>
        <geometry>
          <box size="0.03512 0.04821 0.07179"/>
        </geometry>
      </collision-->
  </link>

  <joint name="left_arm_camera_joint" type="fixed">
    <parent link="left_arm_camera_bracket"/>
    <child link="left_arm_camera"/>
    <origin rpy="-0.625 0 0" xyz="0.0 -0.028 -0.005"/>
  </joint>
  <link name="left_arm_camera">
    <inertial>
      <origin rpy="0 0 0" xyz="0 0 0"/>
      <mass value="0.085"/>
      <!-- inretia tensor for solid cuboid: m=0.085, h=0.065, w=0.024, d=0.024 -->
      <inertia ixx="3.4007e-05" ixy="0" ixz="0" iyy="3.4007e-05" iyz="0" izz="8.16e-06"/>
    </inertial>
    <visual>
      <origin rpy="0 0 0" xyz="0 0 0"/>
      <geometry>
        <box size="0.031 0.028 0.063"/>
      </geometry>
      <material name="blackish">
        <color rgba="0.2 0.2 0.2 1"/>
      </material>
    </visual>
    <collision>
      <origin rpy="0 0 0" xyz="0 0 0"/>
      <geometry>
        <box size="0.036 0.045 0.063"/>
      </geometry>
    </collision>
  </link>

  <!-- PTU -->

  <joint name="ptu_joint" type="fixed">
    <parent link="base_link"/>
    <child link="ptu_base_plate_link"/>
    <origin rpy="0 0 0" xyz="0.02 0 1.1075"/>
  </joint>
  <link name="ptu_base_plate_link">
    <inertial>
      <origin rpy="0 0 0" xyz="-0.034 0 0"/>
      <mass value="0.07"/>
      <!-- inretia tensor for solid cuboid: m=0.07, h=0.005, w=0.142, d=0.17 -->
      <inertia ixx="1.1777e-04" ixy="0" ixz="0" iyy="1.6873e-04" iyz="0" izz="2.8621e-04"/>
    </inertial>
    <visual>
      <origin rpy="0 0 0" xyz="-0.035 0 0.0025"/>
      <geometry>
        <box size="0.17 0.142 0.005"/>
      </geometry>
      <material name="black">
        <color rgba="0.2 0.2 0.2 1"/>
      </material>
    </visual>
  </link>

  <joint name="ptu_base_plate_joint" type="fixed">
    <parent link="ptu_base_plate_link"/>
    <child link="ptu_base_link"/>
    <origin rpy="0 0 0" xyz="0.0 0.0 0.0"/>
  </joint>
  <link name="ptu_base_link">
  </link>

  <joint name="ptu_base_joint" type="fixed">
    <parent link="ptu_base_link"/>
    <child link="ptu_pan_link"/>
    <origin rpy="0 0 0" xyz="0.0 0 0.005"/>
  </joint>
  <link name="ptu_pan_link">
    <inertial>
      <origin rpy="0 0 0" xyz="0 0 0.06"/>
      <mass value="0.13"/>
      <!-- inretia tensor for solid cuboid: m=0.13, h=0.07, w=0.046, d=0.105 -->
      <inertia ixx="7.6006e-05" ixy="0" ixz="0" iyy="1.4136e-04" iyz="0" izz="1.7892e-04"/>
    </inertial>
    <visual>
      <origin rpy="0 0 0" xyz="0 0.0 0.025"/>
      <geometry>
        <mesh filename="package://dp_ptu_46_description/meshes/pan.dae"/>
      </geometry>
    </visual>
    <collision>
      <origin xyz="0 0.0115 0.047"/>
      <geometry>
        <box size="0.154 0.177 0.094"/>
      </geometry>
    </collision>
  </link>

  <joint name="ptu_pan_joint" type="revolute">
    <parent link="ptu_base_link"/>
    <child link="ptu_tilt_link"/>
    <origin rpy="0 0 0" xyz="-0.00436 -0.0067 0.03"/>
    <limit effort="100.0" lower="-2.775" upper="2.775" velocity="1.0"/>
    <axis xyz="0 0 1"/>
  </joint>
  <link name="ptu_tilt_link">
    <inertial>
      <origin rpy="0 0 0" xyz="-0.03 0 0.05"/>
      <mass value="0.13"/>
      <!-- inretia tensor for solid cuboid: m=0.13, h=0.07, w=0.046, d=0.105 -->
      <inertia ixx="7.6006e-05" ixy="0" ixz="0" iyy="1.7252e-04" iyz="0" izz="1.4136e-04"/>
    </inertial>
    <visual>
      <origin rpy="0 0 0" xyz="0.00436 0.0067 0.0"/>
      <geometry>
        <mesh filename="package://dp_ptu_46_description/meshes/tilt.dae"/>
      </geometry>
    </visual>
    <collision>
      <origin xyz="0 0.0115 0.047"/>
      <geometry>
        <box size="0.154 0.177 0.094"/>
      </geometry>
    </collision>
  </link>

  <joint name="ptu_tilt_joint" type="revolute">
    <parent link="ptu_tilt_link"/>
    <child link="ptu_mount_link"/>
    <origin rpy="0 0 0" xyz="0.0 0 0.0659"/>
    <limit effort="100.0" lower="-1.396" upper="0.541" velocity="1.0"/>
    <axis xyz="0 -1 0"/>
  </joint>
  <link name="ptu_mount_link">
    <inertial>
      <origin rpy="0 0 0" xyz="0 0 0.036"/>
      <mass value="0.07"/>
      <!-- inretia tensor for solid cuboid: m=0.07, h=0.007, w=0.052, d=0.025 -->
      <inertia ixx="1.6059e-05" ixy="0" ixz="0" iyy="3.9316e-06" iyz="0" izz="1.9419e-05"/>
    </inertial>
    <visual>
      <origin rpy="0 0 0" xyz="0.00436 0.0067 -0.0659"/>
      <geometry>
        <mesh filename="package://dp_ptu_46_description/meshes/mount.dae"/>
      </geometry>
    </visual>
    <collision>
      <origin xyz="0 0.0115 0.047"/>
      <geometry>
        <box size="0.154 0.177 0.094"/>
      </geometry>
    </collision>
  </link>

  <!-- Hokuyo lidar -->

  <joint name="hokuyo_base_joint" type="fixed">
    <parent link="base_link"/>
    <child link="hokuyo_link"/>
    <origin rpy="0 0 0" xyz="0.1 0 0.3"/>
  </joint>
  <link name="hokuyo_link">
    <inertial>
      <origin rpy="0 0 0" xyz="0 0 -0.02"/>
      <mass value="0.13"/>
      <!-- inretia tensor for solid cuboid: m=0.13, h=0.07, w=0.05, d=0.05 -->
      <inertia ixx="8.0167e-05" ixy="0" ixz="0" iyy="8.0167e-05" iyz="0" izz="5.4167e-05"/>
    </inertial>
    <visual>
      <origin rpy="0 0 0" xyz="0 0 0"/>
      <geometry>
        <cylinder length="0.0265" radius="0.021"/>
      </geometry>
      <material name="blackish"/>
    </visual>
    <visual>
      <origin rpy="0 0 0" xyz="0 0 -0.034"/>
      <geometry>
        <box size="0.05 0.05 0.041"/>
      </geometry>
      <material name="blackish"/>
    </visual>
    <collision>
      <origin rpy="0 0 0" xyz="0 0 0"/>
      <geometry>
        <cylinder length="0.0265" radius="0.021"/>
      </geometry>
    </collision>
    <collision>
      <origin rpy="0 0 0" xyz="0 0 -0.047"/>
      <geometry>
        <box size="0.05 0.05 0.041"/>
      </geometry>
    </collision>
  </link>

  <!-- Bumblebee 2 -->

  <joint name="bumblebee_joint" type="fixed">
    <parent link="ptu_mount_link"/>
    <child link="bumblebee_link"/>
    <origin rpy="0 0 0" xyz="0 0 0.058"/>
  </joint>
  <link name="bumblebee_link">
    <inertial>
      <origin rpy="0 0 0" xyz="0 0 0"/>
      <mass value="0.342"/>
      <!-- inretia tensor for solid cuboid: m=0.342, h=0.036, w=0.157, d=0.0474 -->
      <inertia ixx="7.3943e-04" ixy="0" ixz="0" iyy="1.0096e-04" iyz="0" izz="7.6653e-04"/>
    </inertial>
    <visual>
      <origin rpy="0 0 0" xyz="0 0 0"/>
      <geometry>
        <box size="0.047 0.157 0.038"/>
      </geometry>
      <material name="golden">
        <color rgba="0.4 0.4 0.1 1"/>
      </material>
    </visual>
  </link>

  <joint name="bumblebee_cameras_joint" type="fixed">
    <parent link="bumblebee_link"/>
    <child link="bumblebee_cameras_link"/>
    <origin rpy="0 0 0" xyz="0 0 0.0"/>
  </joint>
  <link name="bumblebee_cameras_link">
    <visual>
      <origin rpy="0 1.5708 0" xyz="0.024 0.06 0"/>
      <geometry>
        <cylinder length="0.001" radius="0.011"/>
      </geometry>
      <material name="glass">
        <color rgba="1 1 1 0.2"/>
      </material>
    </visual>
    <visual>
      <origin rpy="0 1.5708 0" xyz="0.024 -0.06 0"/>
      <geometry>
        <cylinder length="0.001" radius="0.011"/>
      </geometry>
      <material name="glass"/>
    </visual>
  </link>

  <!-- Asus Xtion Pro Live -->

  <joint name="xtion_joint" type="fixed">
    <parent link="bumblebee_link"/>
    <child link="xtion_link"/>
    <origin rpy="0 0 0" xyz="0 0 0.055"/>
  </joint>
  <link name="xtion_link">
    <inertial>
      <origin rpy="0 0 0" xyz="0 0 0"/>
      <mass value="0.54"/>
      <!-- inretia tensor for solid cuboid: m=0.54, h=0.034, w=0.18, d=0.034 -->
      <inertia ixx="1.51e-03" ixy="0" ixz="0" iyy="1.0404e-04" iyz="0" izz="1.51e-03"/>
    </inertial>
    <visual>
      <origin rpy="0 0 0" xyz="0 0 0"/>
      <geometry>
        <box size="0.036 0.178 0.03"/>
      </geometry>
      <material name="blackish"/>
    </visual>
    <visual>
      <origin rpy="0 0 0" xyz="0 0 -0.025"/>
      <geometry>
        <box size="0.02 0.017 0.02"/>
      </geometry>
      <material name="blackish"/>
    </visual>
    <visual>
      <origin rpy="0 0 0" xyz="0 0 -0.035"/>
      <geometry>
        <box size="0.04 0.1 0.004"/>
      </geometry>
      <material name="blackish"/>
    </visual>
  </link>

  <gazebo>
    <plugin name="gazebo_ros_control" filename="libgazebo_ros_control.so">
		<publish_tf>1</publish_tf>
		<robotNamespace>/</robotNamespace>
		<robotSimType>gazebo_ros_control/DefaultRobotHWSim</robotSimType>
		<legacyModeNS>true</legacyModeNS>
	
	</plugin>
	
	<plugin name="joint_state_publisher" filename="libgazebo_ros_joint_state_publisher.so"> 
      <updateRate>50</updateRate>
    </plugin>   
	
  </gazebo>  
  
  <gazebo>
    <plugin filename="libgazebo_ros_diff_drive.so" name="differential_drive_controller">
      <alwaysOn>true</alwaysOn>
      <updateRate>50</updateRate>
      <leftJoint>wheel_left_joint</leftJoint>
      <rightJoint>wheel_right_joint</rightJoint>
      <wheelSeparation>0.44</wheelSeparation>
      <wheelDiameter>0.19</wheelDiameter>
      <torque>0.1</torque>
      <commandTopic>cmd_vel</commandTopic>
      <odometryTopic>odom</odometryTopic>
      <odometryFrame>odom</odometryFrame>
      <robotBaseFrame>base_link</robotBaseFrame>
	  <legacyMode>false</legacyMode>
    </plugin>
  </gazebo>

</robot>
