<?xml version="1.0" ?>
<!-- =================================================================================== -->
<!-- |    This document was autogenerated by xacro from /home/bot/catkin_ws/src/phoebe_stack/phoebe_description/phoebe.urdf.xacro | -->
<!-- |    EDITING THIS FILE BY HAND IS NOT RECOMMENDED                                 | -->
<!-- =================================================================================== -->
<robot name="phoebe" xmlns:xacro="http://www.ros.org/wiki/xacro">
 
 
 <!-- Used for fixing robot to Gazebo 'base_link' -->
  <link name="base_footprint"/>
    
  <joint name="base_joint" type="fixed">
      <origin xyz="0 0 0.0012" rpy="0 0 0" />
      <parent link="base_footprint"/>
      <child link="base_link" />
  </joint> 
  
  <link name="base_link">
    <inertial>
      <origin rpy="0 0 0" xyz="-0.040872 0.0 0.56"/>
      <mass value="12"/>
      <!-- inretia tensor for solid cuboid: m=12, h=1.12, d=0.49, w=0.41 -->
      <inertia ixx="1.4225" ixy="0" ixz="0" iyy="1.4945" iyz="0" izz="0.4082"/>
    </inertial>
    <visual>
      <origin rpy="0 0 0" xyz="0 0 0"/>																																																																		/>																																																																																																																																																																																																																																																																																																																																																																																													
      <geometry>
        <mesh filename="package://phoebe_description/meshes/phoebe.dae"/>
      </geometry>
    </visual>
    <collision>
      <origin rpy="0 0 0" xyz="0 0 0"/>
      <geometry>
        <mesh filename="package://phoebe_description/meshes/phoebe.dae"/>
      </geometry>
    </collision>	
	
  </link>
  
  
  <joint name="wheel_rear_joint" type="continuous">
    <parent link="base_link"/>
    <child link="wheel_rear"/>
    <origin rpy="0 0 0" xyz="-0.29 0.0 0.020"/>
	<axis rpy="0 0 0" xyz="0 1 0"/>
    <limit effort="10000" velocity="1000"/>
    <joint_properties damping="1.0" friction="1.0"/>
    
  </joint>

  <link name="wheel_rear">
    <inertial>
      <!--origin rpy="0 0 0" xyz="0 0 0"/-->
	  <origin rpy="0 1.5707 1.5707" xyz="0 0 0"/>
      <mass value="0.25"/>
      <!-- inretia tensor for solid cylinder: m=0.5, h=0.05, r=0.095 -->
      <inertia ixx="1.232291667e-03" ixy="0" ixz="0" iyy="1.232291667e-03" iyz="0" izz="2.25625e-03"/>
    </inertial>
    <visual>
      <origin rpy="0 1.5707 1.5707" xyz="0 0 0"/>
      <geometry>
        <cylinder length="0.1" radius="0.02"/>
      </geometry>
      <material name="blackish">
        <color rgba="0.2 0.2 0.2 1"/>
      </material>
    </visual>
    <collision>
      <origin rpy="0 1.5707 1.5707" xyz="0 0 0"/>
      <geometry>
        <cylinder length="0.1" radius="0.02"/>
      </geometry>
    </collision>
  </link>
  
  
  <joint name="wheel_front_joint" type="continuous">
    <parent link="base_link"/>
    <child link="wheel_front"/>
    <origin rpy="0 0 0" xyz="0.206 0 0.020"/>
	<axis rpy="0 0 0" xyz="0 1 0"/>
    <limit effort="10000" velocity="1000"/>
    <joint_properties damping="1.0" friction="1.0"/>    
  </joint>
  
  <link name="wheel_front">
    <inertial>
      <!--origin rpy="0 0 0" xyz="0 0 0"/-->
	  <origin rpy="0 1.5707 1.5707" xyz="0 0 0"/>
      <mass value="0.25"/>
      
      <inertia ixx="1.232291667e-03" ixy="0" ixz="0" iyy="1.232291667e-03" iyz="0" izz="2.25625e-03"/>
    </inertial>
    <visual>
     <origin rpy="0 1.5707 1.5707" xyz="0 0 0"/>
     <geometry>
        <cylinder length="0.1" radius="0.02"/>
      </geometry>
      <material name="blackish"/>
    </visual>
    <collision>
      <origin rpy="0 1.5707 1.5707" xyz="0 0 0"/>
      <geometry>
        <cylinder length="0.1" radius="0.02"/>
      </geometry>
    </collision>
  </link>
  
  
  
  <joint name="wheel_left_joint" type="continuous">
    <parent link="base_link"/>
    <child link="wheel_left"/>
	<!--origin rpy="1.570796 0 0" xyz="0.0 0.18 0.095"/-->
    <origin rpy="0 0 0" xyz="0.0 0.18 0.095"/>
    <!--axis xyz="0 0 1"/-->
	<axis xyz="0 1 0"/>
	<limit effort="10000" velocity="1000"/>
    <joint_properties damping="1.0" friction="1.0"/>
  </joint>

  <link name="wheel_left">
    <inertial>
      <!--origin rpy="0 0 0" xyz="0 0 0"/-->
	  <origin rpy="0 1.5707 1.5707" xyz="0 0 0"/>
      <mass value="0.5"/>
      <!-- inretia tensor for solid cylinder: m=0.5, h=0.05, r=0.095 -->
      <inertia ixx="1.232291667e-03" ixy="0" ixz="0" iyy="1.232291667e-03" iyz="0" izz="2.25625e-03"/>
    </inertial>
    <visual>
      <!--origin rpy="0 0 0" xyz="0 0 0"/-->
	  <origin rpy="0 1.5707 1.5707" xyz="0 0 0"/>
      <geometry>
        <cylinder length="0.05" radius="0.095"/>
      </geometry>
      <material name="blackish">
        <color rgba="0.2 0.2 0.2 1"/>
      </material>
    </visual>
    <collision>
      <!--origin rpy="0 0 0" xyz="0 0 0"/-->
	  <origin rpy="0 1.5707 1.5707" xyz="0 0 0"/>
      <geometry>
        <cylinder length="0.05" radius="0.095"/>
      </geometry>
    </collision>
  </link>
  
  
  <joint name="wheel_right_joint" type="continuous">
    <parent link="base_link"/>
    <child link="wheel_right"/>
    <!--origin rpy="1.570796 0 0" xyz="0.0 -0.18 0.095"/-->
	<origin rpy="0 0 0" xyz="0.0 -0.18 0.095"/>
    <!--axis xyz="0 0 1"/-->
	<axis xyz="0 1 0"/>
	<limit effort="10000" velocity="1000"/>
    <joint_properties damping="1.0" friction="1.0"/>
  </joint>
  <link name="wheel_right">
    <inertial>
      <!--origin rpy="0 0 0" xyz="0 0 0"/-->
	  <origin rpy="0 1.5707 1.5707" xyz="0 0 0"/>
      <mass value="0.5"/>
      <!-- inretia tensor for solid cylinder: m=0.5, h=0.05, r=0.095 -->
      <inertia ixx="1.232291667e-03" ixy="0" ixz="0" iyy="1.232291667e-03" iyz="0" izz="2.25625e-03"/>
    </inertial>
    <visual>
      <!--origin rpy="0 0 0" xyz="0 0 0"/-->
	  <origin rpy="0 1.5707 1.5707" xyz="0 0 0"/>
      <geometry>
        <cylinder length="0.05" radius="0.095"/>
      </geometry>
      <material name="blackish"/>
    </visual>
    <collision>
      <!--origin rpy="0 0 0" xyz="0 0 0"/-->
	  <origin rpy="0 1.5707 1.5707" xyz="0 0 0"/>
      <geometry>
        <cylinder length="0.05" radius="0.095"/>
      </geometry>
    </collision>
  </link>
  

  <!-- Cyton Gamma 1500 models -->

  <!-- Right arm -->
	
  <joint name="right_arm_joint" type="fixed">
    <parent link="base_link"/>
    <child link="right_arm_base_link"/>
    <origin rpy="1.5708 -1.5708 0" xyz="0.067 -0.162 0.8"/>
  </joint>
  
  
  <link name="right_arm_base_link">
    <inertial>
      <origin rpy="0 0 0" xyz="0.0 0 0"/>
      <mass value="0.478571"/>
      <!-- inretia tensor for solid cuboid: m=0.478571, w=0.177, h=0.074, d=0.150 -->
      <inertia ixx="1.47e-03" ixy="0" ixz="0" iyy="2.15e-03" iyz="0" izz="1.12e-03"/>
    </inertial>
    <visual>
      <origin rpy="0 0 0" xyz="0 0 0"/>
      <geometry>
        <mesh filename="package://cyton_gamma_1500_description/meshes/base.dae"/>
      </geometry>
    </visual>
    <collision>
      <origin xyz="0 0.0115 0.047"/>
      <geometry>
        <box size="0.154 0.177 0.094"/>
      </geometry>
    </collision>
  </link>
  
  <gazebo reference="right_arm_base_link">
        <kp>10000000000.0</kp>
        <kd>10.0</kd>
        <mu1>10.0</mu1>
        <mu2>10.0</mu2>
        <material>Gazebo/Black</material>
  </gazebo>

  <joint name="right_arm_shoulder_roll_joint" type="revolute">
    <parent link="right_arm_base_link"/>
    <child link="right_arm_shoulder_roll"/>
    <origin rpy="0 0 0" xyz="0 0 0.05315"/>
    <limit effort="100.0" lower="-2.618" upper="2.618" velocity="5.0"/>
    <axis xyz="0 0 1"/>
  </joint>
  
  <link name="right_arm_shoulder_roll">
    <inertial>
      <origin rpy="0 0 0" xyz="0 0 0.12"/>
      <mass value="0.468571"/>
      <!-- inretia tensor for solid cylinder: m=0.468571, h=0.09248, r=0.044737 -->
      <inertia ixx="4.7e-04" ixy="0" ixz="0" iyy="5.7e-04" iyz="0" izz="5.7e-04"/>
    </inertial>
    <visual>
      <origin rpy="1.5708 0 0.384" xyz="0 0 0"/>
      <geometry>
        <mesh filename="package://cyton_gamma_1500_description/meshes/shoulder_roll.dae"/>
      </geometry>
    </visual>
    <collision>
      <origin xyz="0.0 0.0 0.05"/>
      <geometry>
	
        <box size="0.09829 0.046 0.08392"/>
      </geometry>
    </collision>
  </link>

  <joint name="right_arm_shoulder_pitch_joint" type="revolute">
    <parent link="right_arm_shoulder_roll"/>
    <child link="right_arm_shoulder_pitch"/>
    <origin rpy="0 0 0" xyz="0.0205 0 0.12435"/>
    <limit effort="100.0" lower="-1.8326" upper="1.8326" velocity="5.0"/>
    <axis xyz="1 0 0"/>
  </joint>
  
  <link name="right_arm_shoulder_pitch">
    <inertial>
      <!--origin rpy="0 0 0" xyz="-0.0214 0 0.117"/-->
	  <origin rpy="0 0 0" xyz="0 0 0"/>
      <mass value="0.4285714"/>
      <!-- inretia tensor for solid cylinder: m=0.4285714, h=0.09248, r=0.04204 -->
      <inertia ixx="4.9e-04" ixy="0" ixz="0" iyy="3.8e-04" iyz="0" izz="4.9e-04"/>
    </inertial>
    <visual>
      <origin rpy="1.5708 0 0" xyz="0 0 0"/>
      <geometry>
        <mesh filename="package://cyton_gamma_1500_description/meshes/shoulder_pitch.dae"/>
      </geometry>
    </visual>
   <collision>
      <origin xyz="-0.02 0.0 0.0"/>
      <geometry>
		<sphere radius="0.055"/>
        <!--box size="0.098 0.08 0.11"/-->
      </geometry>
    </collision>
  </link>

  <joint name="right_arm_shoulder_yaw_joint" type="revolute">
    <parent link="right_arm_shoulder_pitch"/>
    <child link="right_arm_shoulder_yaw"/>
    <origin rpy="0 0 0" xyz="-0.0215 -0.0205 0.1255"/>
    <limit effort="100.0" lower="-1.8326" upper="1.8326" velocity="5.0"/>
    <axis xyz="0 -1 0"/>
  </joint>
  
  <link name="right_arm_shoulder_yaw">
    <inertial>
      <!--origin rpy="0 0 0" xyz="-0.002 0.021 0.1135"/-->
	  <origin rpy="0 0 0" xyz="0 0 0"/>
      <mass value="0.408571"/>
      <!-- inretia tensor for solid cylinder: m=0.408571, h=0.084081, r=0.036785 -->
      <inertia ixx="2.8e-04" ixy="0" ixz="0" iyy="3.8e-04" iyz="0" izz="3.8e-04"/>
    </inertial>
    <visual>
      <origin rpy="1.5708 0 -1.5708" xyz="0 0 0.0"/>
      <geometry>
        <mesh filename="package://cyton_gamma_1500_description/meshes/shoulder_yaw.dae"/>
      </geometry>
    </visual>
    <collision>
      <origin xyz=" -0.002 0.02 -0.01"/>
      <geometry>
		<sphere radius="0.055"/>
        <!--box size="0.08 0.1 0.11"/-->
      </geometry>
    </collision>
  </link>

  <joint name="right_arm_elbow_pitch_joint" type="revolute">
    <parent link="right_arm_shoulder_yaw"/>
    <child link="right_arm_elbow_pitch"/>
    <origin rpy="0 0 0" xyz="0.018 0.0206 0.1158"/>
    <limit effort="100.0" lower="-1.8326" upper="1.8326" velocity="5.0"/>
    <axis xyz="1 0 0"/>
  </joint>
  
  <link name="right_arm_elbow_pitch">
    <inertial>
	  <origin rpy="0 0 0" xyz="0 0 0"/>
      <!--origin rpy="0 0 0" xyz="-0.0176 0.001 0.095"/-->
      <mass value="0.388671"/>
      <!-- inretia tensor for solid cylinder: m=0.388671, h=0.06705, r=0.028975 -->
      <inertia ixx="2.3e-04" ixy="0" ixz="0" iyy="1.6e-04" iyz="0" izz="2.3e-04"/>
    </inertial>
    <visual>
      <origin rpy="1.5708 0 3.1416" xyz="0 0 0"/>
      <geometry>
        <mesh filename="package://cyton_gamma_1500_description/meshes/elbow_pitch.dae"/>
      </geometry>
    </visual>
    <collision>
      <origin xyz="-0.022 0.0 -0.006"/>
      <geometry>
		<sphere radius="0.055"/>
        <!--box size="0.09 0.1 0.11"/-->
      </geometry>
    </collision>
  </link>

  <joint name="right_arm_elbow_yaw_joint" type="revolute">
    <parent link="right_arm_elbow_pitch"/>
    <child link="right_arm_elbow_yaw"/>
    <origin rpy="0 0 0" xyz="-0.0171 -0.018 0.09746"/>
    <limit effort="100.0" lower="-1.8326" upper="1.8326" velocity="5.0"/>
    <axis xyz="0 -1 0"/>
  </joint>
  
  <link name="right_arm_elbow_yaw">
    <inertial>
      <!--origin rpy="0 0 0" xyz="0 0.018 0.073"/-->
	  <origin rpy="0 0 0" xyz="0 0 0"/>
      <mass value="0.368871"/>
      <!-- inretia tensor for solid cylinder: m=0.368871, h=0.043602, r=0.024071 -->
      <inertia ixx="1.0686e-04" ixy="0" ixz="0" iyy="1.1187e-04" iyz="0" izz="1.1187e-04"/>
    </inertial>
    <visual>
      <origin rpy="1.5708 0 1.5708" xyz="0 0 0"/>
      <geometry>
        <mesh filename="package://cyton_gamma_1500_description/meshes/elbow_yaw.dae"/>
      </geometry>
    </visual>
    <collision>
      <origin xyz="0.0 0.025 0.0"/>
      <geometry>
		<sphere radius="0.05"/>
      </geometry>
    </collision>
  </link>

  <joint name="right_arm_wrist_pitch_joint" type="revolute">
    <parent link="right_arm_elbow_yaw"/>
    <child link="right_arm_wrist_pitch"/>
    <origin rpy="0 0 0" xyz="0.02626 0.018 0.0718"/>
    <limit effort="100.0" lower="-1.8326" upper="1.8326" velocity="5.0"/>
    <axis xyz="-1 0 0"/>
  </joint>
  
  <link name="right_arm_wrist_pitch">
    <inertial>
      <!--origin rpy="0 0 0" xyz="-0.027 -0.0005 0.028"/-->
	  <origin rpy="0 0 0" xyz="0 0 0"/>
      <!-- <mass value="0.008"/> -->
	  <mass value="0.2"/>
      <!-- inretia tensor for solid cuboid: m=0.008, h=0.045602, w=0.0218, d=0.005 -->
      <!-- <inertia ixx="3.3349e-07" ixy="0" ixz="0" iyy="1.403e-06" iyz="0" izz="1.70319e-06"/> -->
	  <inertia ixx="8.337e-06" ixy="0" ixz="0" iyy="3.507e-05" iyz="0" izz="4.258e-05"/>
    </inertial>
    <visual>
      <origin rpy="1.5708 0 1.5708" xyz="0 0 0"/>
      <geometry>
        <mesh filename="package://cyton_gamma_1500_description/meshes/wrist_pitch.dae"/>
      </geometry>
    </visual>
     <collision>
      <origin xyz="-0.02 0.0 0.0"/>
      <geometry>
		<box size="0.07 0.06 0.11"/>
      </geometry>
    </collision>
  </link>  

  <joint name="right_arm_wrist_roll_joint" type="revolute">
    <parent link="right_arm_wrist_pitch"/>
    <child link="right_arm_wrist_roll"/>
    <origin rpy="0 0 0" xyz="-0.026255 0 0.051425"/>
    <limit effort="100.0" lower="-2.61799" upper="2.61799" velocity="5.0"/>
    <axis xyz="0 0 1"/>
  </joint>
  
  <link name="right_arm_wrist_roll">
    <inertial>
      <!--origin rpy="0 0 0" xyz="0 0 0.029"/-->
	  <origin rpy="0 0 0" xyz="0 0 0"/>
      <mass value="0.38"/>
      <!-- inretia tensor for solid cylinder: m=0.38, h=0.095, r=0.027975 -->
      <inertia ixx="3.6e-04" ixy="0" ixz="0" iyy="3.6e-04" iyz="0" izz="1.487e-04"/>
    </inertial>
    <visual>
      <origin rpy="3.1416 0 -1.5708" xyz="0 0 0"/>
      <geometry>
        <mesh filename="package://cyton_gamma_1500_description/meshes/wrist_roll.dae"/>
      </geometry>
    </visual>
     <collision>
      <origin xyz="0.0 0.008 0.04"/>
      <geometry>	
        <box size="0.08 0.06 0.08"/>
      </geometry>
    </collision>
  </link>

  <joint name="right_arm_gripper_joint" type="prismatic">
    <parent link="right_arm_wrist_roll"/>
    <child link="right_arm_gripper_finger1"/>
    <origin rpy="0 0 0" xyz="-0.01331 0.00485 0.077225"/>
    <limit effort="100.0" lower="-0.008" upper="0.008" velocity="5.0"/>
    <axis xyz="1 0 0"/>
  </joint>
  
  <link name="right_arm_gripper_finger1">
    <inertial>
      <!--origin rpy="0 0 0" xyz="-0.0036 0.0096 0.017"/-->
	  <origin rpy="0 0 0" xyz="0 0 0"/>
      <mass value="0.035"/>
      <!-- inretia tensor for solid cuboid: m=0.035, h=0.0323, w=0.01469, d=0.0224 -->
      <inertia ixx="4.5064e-06" ixy="0" ixz="0" iyy="3.6723e-06" iyz="0" izz="2.0929e-06"/>
    </inertial>
    <visual>
      <origin rpy="0 0 0" xyz="0 0 0"/>
      <geometry>
        <mesh filename="package://cyton_gamma_1500_description/meshes/gripper_finger1.dae"/>
      </geometry>
    </visual>
    <collision>
      <!--origin xyz="-0.0167 0.0172 0.7254"/-->
	  <origin xyz="0.0 0.007 0.02"/>
      <geometry>
        <!-- <box size="0.015 0.0229 0.0475"/> -->
		<box size="0.010 0.02 0.031"/>
      </geometry>
    </collision>
  </link>

  <joint name="right_arm_gripper_joint2" type="prismatic">
    <parent link="right_arm_wrist_roll"/>
    <child link="right_arm_gripper_finger2"/>
    <origin rpy="0 0 0" xyz="0.0098 0.00485 0.077225"/>
    <limit effort="100.0" lower="-0.008" upper="0.008" velocity="5.0"/>
    <mimic joint="right_arm_gripper_joint" multiplier="-1"/>
    <axis xyz="1 0 0"/>
  </joint>
  <link name="right_arm_gripper_finger2">
    <inertial>
      <!--origin rpy="0 0 0" xyz="0.0034 0.0096 0.017"/-->
	  <origin rpy="0 0 0" xyz="0 0 0"/>
      <mass value="0.035"/>
      <!-- inretia tensor for solid cuboid: m=0.035, h=0.0323, w=0.01469, d=0.0224 -->
      <inertia ixx="4.5064e-06" ixy="0" ixz="0" iyy="3.6723e-06" iyz="0" izz="2.0929e-06"/>
    </inertial>
    <visual>
      <origin rpy="0 0 0" xyz="0 0 0"/>
      <geometry>
        <mesh filename="package://cyton_gamma_1500_description/meshes/gripper_finger2.dae"/>
      </geometry>
    </visual>
    <collision>
      <!--origin xyz="0.0132 0.0172 0.7254"/-->
	  <origin xyz="0.0 0.007 0.02"/>
      <geometry>
        <!-- <box size="0.015 0.0229 0.0475"/> -->
		<box size="0.010 0.020 0.031"/>
      </geometry>
    </collision>
  </link>

  <!-- virtual end-effector -->

  <joint name="right_arm_virtual_endeffector_joint" type="fixed">
    <parent link="right_arm_wrist_roll"/>
    <child link="right_arm_virtual_endeffector"/>
    <origin rpy="0 0 0" xyz="-0.002316 0.0079 0.079425"/>
  </joint>
  <link name="right_arm_virtual_endeffector">
    <inertial>
      <origin rpy="0 0 0" xyz="0 0 0"/>
      <mass value="0.0016"/>
      <!-- inretia tensor for solid sphere: m=0.0016, r=0.0022 -->
      <inertia ixx="3.0976e-09" ixy="0" ixz="0" iyy="3.0976e-09" iyz="0" izz="3.0976e-09"/>
    </inertial>
    <visual>
      <origin rpy="0 0 0" xyz="0 0 0"/>
      <geometry>
        <sphere radius="0.002"/>
      </geometry>
      <material name="grey">
        <color rgba="0.7 0.7 0.7 0.8"/>
      </material>
    </visual>
  </link>

  <joint name="right_arm_camera_bracket_joint" type="fixed">
    <parent link="right_arm_wrist_roll"/>
    <child link="right_arm_camera_bracket"/>
    <origin rpy="0 0 0" xyz="-0.0008 -0.028 0.0435"/>
  </joint>
  <link name="right_arm_camera_bracket">
    <inertial>
      <origin rpy="0.95 0 0" xyz="0 -0.01 -0.012"/>
      <mass value="0.052"/>
      <!-- inretia tensor for solid cuboid: m=0.052, h=0.071, w=0.028, d=0.0086 -->
      <inertia ixx="2.2165e-05" ixy="0" ixz="0" iyy="3.7178e-06" iyz="0" izz="2.5242e-05"/>
    </inertial>
    <visual>
      <origin rpy="0 0 0" xyz="0 0 0"/>
      <geometry>
        <mesh filename="package://cyton_gamma_1500_minicam_description/meshes/cam_bracket.dae"/>
      </geometry>
    </visual>
    <collision>
        <origin xyz="0.0 0.0 0.0"/>
        <geometry>
          <box size="0.03512 0.04821 0.07179"/>
        </geometry>
      </collision>
  </link>

  <joint name="right_arm_camera_joint" type="fixed">
    <parent link="right_arm_camera_bracket"/>
    <child link="right_arm_camera"/>
    <origin rpy="0  -1.57 3.14" xyz="0.0 -0.028 -0.005"/>	
  </joint>
  
  <link name="right_arm_camera">
    <inertial>
      <origin rpy="0 0 0" xyz="0 0 0"/>
      <mass value="0.085"/>
      <!-- inretia tensor for solid cuboid: m=0.085, h=0.065, w=0.024, d=0.024 -->
      <inertia ixx="3.4007e-05" ixy="0" ixz="0" iyy="3.4007e-05" iyz="0" izz="8.16e-06"/>
    </inertial>
    <visual>
      <origin rpy="0 0 0" xyz="0 0 0"/>
      <geometry>
        <!-- <box size="0.031 0.028 0.063"/> -->
		<box size=" 0.063 0.028  0.031"/>
      </geometry>
      <material name="blackish">
        <color rgba="0.2 0.2 0.2 1"/>
      </material>
    </visual>
    <collision>
      <origin rpy="0 0 0" xyz="0 0 0"/>
      <geometry>
        <!-- <box size="0.036 0.045 0.063"/> -->
		<box size="0.063 0.045 0.036 "/>
      </geometry>
    </collision>
  </link>

  <!-- Left arm -->

  <joint name="left_arm_joint" type="fixed">
    <parent link="base_link"/>
    <child link="left_arm_base_link"/>
    <origin rpy="-1.5708 1.5708 0" xyz="0.067 0.162 0.8"/>
  </joint>
  
  <link name="left_arm_base_link">
    <inertial>
      <origin rpy="0 0 0" xyz="0.0 0 0"/>
      <mass value="0.478571"/>
      <!-- inretia tensor for solid cuboid: m=0.478571, w=0.177, h=0.074, d=0.150 -->
      <inertia ixx="1.47e-03" ixy="0" ixz="0" iyy="2.15e-03" iyz="0" izz="1.12e-03"/>
    </inertial>
    <visual>
      <origin rpy="0 0 0" xyz="0 0 0"/>
      <geometry>
        <mesh filename="package://cyton_gamma_1500_description/meshes/base.dae"/>
      </geometry>
    </visual>
    <collision>
      <origin xyz="0 0.0115 0.047"/>
      <geometry>
        <box size="0.154 0.177 0.094"/>
      </geometry>
    </collision>
  </link>
  <gazebo reference="left_arm_base_link">
        <kp>10000000000.0</kp>
        <kd>10.0</kd>
        <mu1>10.0</mu1>
        <mu2>10.0</mu2>
        <material>Gazebo/Black</material>
  </gazebo>
  
  <joint name="left_arm_shoulder_roll_joint" type="revolute">
    <parent link="left_arm_base_link"/>
    <child link="left_arm_shoulder_roll"/>
    <origin rpy="0 0 0" xyz="0 0 0.05315"/>
    <limit effort="100.0" lower="-2.618" upper="2.618" velocity="5.0"/>
    <axis xyz="0 0 1"/>
  </joint>

  <link name="left_arm_shoulder_roll">
    <inertial>
      <origin rpy="0 0 0" xyz="0 0 0.12"/>
      <mass value="0.468571"/>
      <!-- inretia tensor for solid cylinder: m=0.468571, h=0.09248, r=0.044737 -->
      <inertia ixx="4.7e-04" ixy="0" ixz="0" iyy="5.7e-04" iyz="0" izz="5.7e-04"/>
    </inertial>
    <visual>
      <origin rpy="1.5708 0 0.384" xyz="0 0 0"/>
      <geometry>
        <mesh filename="package://cyton_gamma_1500_description/meshes/shoulder_roll.dae"/>
      </geometry>
    </visual>
    <collision>
      <origin xyz="0.0 0.0 0.05"/>
      <geometry>
	
        <box size="0.09829 0.046 0.08392"/>
      </geometry>
    </collision>
  </link>

  <joint name="left_arm_shoulder_pitch_joint" type="revolute">
    <parent link="left_arm_shoulder_roll"/>
    <child link="left_arm_shoulder_pitch"/>
    <origin rpy="0 0 0" xyz="0.0205 0 0.12435"/>
    <limit effort="100.0" lower="-1.8326" upper="1.8326" velocity="5.0"/>
    <axis xyz="1 0 0"/>
  </joint>
  
  <link name="left_arm_shoulder_pitch">
    <inertial>
      <!--origin rpy="0 0 0" xyz="-0.0214 0 0.117"/-->
	  <origin rpy="0 0 0" xyz="0 0 0"/>
      <mass value="0.4285714"/>
      <!-- inretia tensor for solid cylinder: m=0.4285714, h=0.09248, r=0.04204 -->
      <inertia ixx="4.9e-04" ixy="0" ixz="0" iyy="3.8e-04" iyz="0" izz="4.9e-04"/>
    </inertial>
    <visual>
      <origin rpy="1.5708 0 0" xyz="0 0 0"/>
      <geometry>
        <mesh filename="package://cyton_gamma_1500_description/meshes/shoulder_pitch.dae"/>
      </geometry>
    </visual>
   <collision>
      <origin xyz="-0.02 0.0 0.0"/>
      <geometry>
		<sphere radius="0.055"/>
        <!--box size="0.098 0.08 0.11"/-->
      </geometry>
    </collision>
  </link>

  <joint name="left_arm_shoulder_yaw_joint" type="revolute">
    <parent link="left_arm_shoulder_pitch"/>
    <child link="left_arm_shoulder_yaw"/>
    <origin rpy="0 0 0" xyz="-0.0215 -0.0205 0.1255"/>
    <limit effort="100.0" lower="-1.8326" upper="1.8326" velocity="5.0"/>
    <axis xyz="0 -1 0"/>
  </joint>
  
  <link name="left_arm_shoulder_yaw">
    <inertial>
      <!--origin rpy="0 0 0" xyz="-0.002 0.021 0.1135"/-->
	  <origin rpy="0 0 0" xyz="0 0 0"/>
      <mass value="0.408571"/>
      <!-- inretia tensor for solid cylinder: m=0.408571, h=0.084081, r=0.036785 -->
      <inertia ixx="2.8e-04" ixy="0" ixz="0" iyy="3.8e-04" iyz="0" izz="3.8e-04"/>
    </inertial>
    <visual>
      <origin rpy="1.5708 0 -1.5708" xyz="0 0 0.0"/>
      <geometry>
        <mesh filename="package://cyton_gamma_1500_description/meshes/shoulder_yaw.dae"/>
      </geometry>
    </visual>
    <collision>
      <origin xyz=" -0.002 0.02 -0.01"/>
      <geometry>
		<sphere radius="0.055"/>
        <!--box size="0.08 0.1 0.11"/-->
      </geometry>
    </collision>
  </link>

  <joint name="left_arm_elbow_pitch_joint" type="revolute">
    <parent link="left_arm_shoulder_yaw"/>
    <child link="left_arm_elbow_pitch"/>
    <origin rpy="0 0 0" xyz="0.018 0.0206 0.1158"/>
    <limit effort="100.0" lower="-1.8326" upper="1.8326" velocity="5.0"/>
    <axis xyz="1 0 0"/>
  </joint>
  
  <link name="left_arm_elbow_pitch">
    <inertial>
	  <origin rpy="0 0 0" xyz="0 0 0"/>
      <!--origin rpy="0 0 0" xyz="-0.0176 0.001 0.095"/-->
      <mass value="0.388671"/>
      <!-- inretia tensor for solid cylinder: m=0.388671, h=0.06705, r=0.028975 -->
      <inertia ixx="2.3e-04" ixy="0" ixz="0" iyy="1.6e-04" iyz="0" izz="2.3e-04"/>
    </inertial>
    <visual>
      <origin rpy="1.5708 0 3.1416" xyz="0 0 0"/>
      <geometry>
        <mesh filename="package://cyton_gamma_1500_description/meshes/elbow_pitch.dae"/>
      </geometry>
    </visual>
    <collision>
      <origin xyz="-0.022 0.0 -0.006"/>
      <geometry>
		<sphere radius="0.055"/>
        <!--box size="0.09 0.1 0.11"/-->
      </geometry>
    </collision>
  </link>

  <joint name="left_arm_elbow_yaw_joint" type="revolute">
    <parent link="left_arm_elbow_pitch"/>
    <child link="left_arm_elbow_yaw"/>
    <origin rpy="0 0 0" xyz="-0.0171 -0.018 0.09746"/>
    <limit effort="100.0" lower="-1.8326" upper="1.8326" velocity="5.0"/>
    <axis xyz="0 -1 0"/>
  </joint>
  
  <link name="left_arm_elbow_yaw">
    <inertial>
      <!--origin rpy="0 0 0" xyz="0 0.018 0.073"/-->
	  <origin rpy="0 0 0" xyz="0 0 0"/>
      <mass value="0.368871"/>
      <!-- inretia tensor for solid cylinder: m=0.368871, h=0.043602, r=0.024071 -->
      <inertia ixx="1.0686e-04" ixy="0" ixz="0" iyy="1.1187e-04" iyz="0" izz="1.1187e-04"/>
    </inertial>
    <visual>
      <origin rpy="1.5708 0 1.5708" xyz="0 0 0"/>
      <geometry>
        <mesh filename="package://cyton_gamma_1500_description/meshes/elbow_yaw.dae"/>
      </geometry>
    </visual>
    <collision>
      <origin xyz="0.0 0.025 0.0"/>
      <geometry>
		<sphere radius="0.05"/>
      </geometry>
    </collision>
  </link>

  <joint name="left_arm_wrist_pitch_joint" type="revolute">
    <parent link="left_arm_elbow_yaw"/>
    <child link="left_arm_wrist_pitch"/>
    <origin rpy="0 0 0" xyz="0.02626 0.018 0.0718"/>
    <limit effort="100.0" lower="-1.8326" upper="1.8326" velocity="5.0"/>
    <axis xyz="-1 0 0"/>
  </joint>
  
  <link name="left_arm_wrist_pitch">
    <inertial>
      <!--origin rpy="0 0 0" xyz="-0.027 -0.0005 0.028"/-->
	  <origin rpy="0 0 0" xyz="0 0 0"/>
      <!-- <mass value="0.008"/> -->
	  <mass value="0.2"/>
      <!-- inretia tensor for solid cuboid: m=0.008, h=0.045602, w=0.0218, d=0.005 -->
      <!-- <inertia ixx="3.3349e-07" ixy="0" ixz="0" iyy="1.403e-06" iyz="0" izz="1.70319e-06"/> -->
	  <inertia ixx="8.337e-06" ixy="0" ixz="0" iyy="3.507e-05" iyz="0" izz="4.258e-05"/>
    </inertial>
    <visual>
      <origin rpy="1.5708 0 1.5708" xyz="0 0 0"/>
      <geometry>
        <mesh filename="package://cyton_gamma_1500_description/meshes/wrist_pitch.dae"/>
      </geometry>
    </visual>
     <collision>
      <origin xyz="-0.02 0.0 0.0"/>
      <geometry>
		<box size="0.07 0.06 0.11"/>
      </geometry>
    </collision>
  </link>  

  <joint name="left_arm_wrist_roll_joint" type="revolute">
    <parent link="left_arm_wrist_pitch"/>
    <child link="left_arm_wrist_roll"/>
    <origin rpy="0 0 0" xyz="-0.026255 0 0.051425"/>
    <limit effort="100.0" lower="-2.61799" upper="2.61799" velocity="5.0"/>
    <axis xyz="0 0 1"/>
  </joint>
  
  <link name="left_arm_wrist_roll">
    <inertial>
      <!--origin rpy="0 0 0" xyz="0 0 0.029"/-->
	  <origin rpy="0 0 0" xyz="0 0 0"/>
      <mass value="0.38"/>
      <!-- inretia tensor for solid cylinder: m=0.38, h=0.095, r=0.027975 -->
      <inertia ixx="3.6e-04" ixy="0" ixz="0" iyy="3.6e-04" iyz="0" izz="1.487e-04"/>
    </inertial>
    <visual>
      <origin rpy="3.1416 0 -1.5708" xyz="0 0 0"/>
      <geometry>
        <mesh filename="package://cyton_gamma_1500_description/meshes/wrist_roll.dae"/>
      </geometry>
    </visual>
     <collision>
      <origin xyz="0.0 0.008 0.04"/>
      <geometry>	
        <box size="0.08 0.06 0.08"/>
      </geometry>
    </collision>
  </link>

  <joint name="left_arm_gripper_joint" type="prismatic">
    <parent link="left_arm_wrist_roll"/>
    <child link="left_arm_gripper_finger1"/>
    <origin rpy="0 0 0" xyz="-0.01331 0.00485 0.077225"/>
    <limit effort="100.0" lower="-0.008" upper="0.008" velocity="5.0"/>
    <axis xyz="1 0 0"/>
  </joint>
  
  <link name="left_arm_gripper_finger1">
    <inertial>
      <!--origin rpy="0 0 0" xyz="-0.0036 0.0096 0.017"/-->
	  <origin rpy="0 0 0" xyz="0 0 0"/>
      <mass value="0.035"/>
      <!-- inretia tensor for solid cuboid: m=0.035, h=0.0323, w=0.01469, d=0.0224 -->
      <inertia ixx="4.5064e-06" ixy="0" ixz="0" iyy="3.6723e-06" iyz="0" izz="2.0929e-06"/>
    </inertial>
    <visual>
      <origin rpy="0 0 0" xyz="0 0 0"/>
      <geometry>
        <mesh filename="package://cyton_gamma_1500_description/meshes/gripper_finger1.dae"/>
      </geometry>
    </visual>
    <collision>
      <!--origin xyz="-0.0167 0.0172 0.7254"/-->
	  <origin xyz="0.0 0.007 0.02"/>
      <geometry>
        <!-- <box size="0.015 0.0229 0.0475"/> -->
		<box size="0.010 0.020 0.031"/>
      </geometry>
    </collision>
  </link>

  <joint name="left_arm_gripper_joint2" type="prismatic">
    <parent link="left_arm_wrist_roll"/>
    <child link="left_arm_gripper_finger2"/>
    <origin rpy="0 0 0" xyz="0.0098 0.00485 0.077225"/>
    <limit effort="100.0" lower="-0.008" upper="0.008" velocity="5.0"/>
    <mimic joint="left_arm_gripper_joint" multiplier="-1"/>
    <axis xyz="1 0 0"/>
  </joint>
  <link name="left_arm_gripper_finger2">
    <inertial>
      <!--origin rpy="0 0 0" xyz="0.0034 0.0096 0.017"/-->
	  <origin rpy="0 0 0" xyz="0 0 0"/>
      <mass value="0.035"/>
      <!-- inretia tensor for solid cuboid: m=0.035, h=0.0323, w=0.01469, d=0.0224 -->
      <inertia ixx="4.5064e-06" ixy="0" ixz="0" iyy="3.6723e-06" iyz="0" izz="2.0929e-06"/>
    </inertial>
    <visual>
      <origin rpy="0 0 0" xyz="0 0 0"/>
      <geometry>
        <mesh filename="package://cyton_gamma_1500_description/meshes/gripper_finger2.dae"/>
      </geometry>
    </visual>
    <collision>
      <!--origin xyz="0.0132 0.0172 0.7254"/-->
	  <origin xyz="0.0 0.007 0.02"/>
      <geometry>
        <!-- <box size="0.015 0.0229 0.0475"/> -->
		<box size="0.010 0.020 0.031"/>
      </geometry>
    </collision>
  </link>

  <!-- virtual end-effector -->

  <joint name="left_arm_virtual_endeffector_joint" type="fixed">
    <parent link="left_arm_wrist_roll"/>
    <child link="left_arm_virtual_endeffector"/>
    <origin rpy="0 0 0" xyz="-0.002316 0.0079 0.079425"/>
  </joint>
  <link name="left_arm_virtual_endeffector">
    <inertial>
      <origin rpy="0 0 0" xyz="0 0 0"/>
      <mass value="0.0016"/>
      <!-- inretia tensor for solid sphere: m=0.0016, r=0.0022 -->
      <inertia ixx="3.0976e-09" ixy="0" ixz="0" iyy="3.0976e-09" iyz="0" izz="3.0976e-09"/>
    </inertial>
    <visual>
      <origin rpy="0 0 0" xyz="0 0 0"/>
      <geometry>
        <sphere radius="0.002"/>
      </geometry>
      <material name="grey">
        <color rgba="0.7 0.7 0.7 0.8"/>
      </material>
    </visual>
  </link>

  <joint name="left_arm_camera_bracket_joint" type="fixed">
    <parent link="left_arm_wrist_roll"/>
    <child link="left_arm_camera_bracket"/>
    <origin rpy="0 0 0" xyz="-0.0008 -0.028 0.0435"/>
  </joint>
  <link name="left_arm_camera_bracket">
    <inertial>
      <origin rpy="0.95 0 0" xyz="0 -0.01 -0.012"/>
      <mass value="0.052"/>
      <!-- inretia tensor for solid cuboid: m=0.052, h=0.071, w=0.028, d=0.0086 -->
      <inertia ixx="2.2165e-05" ixy="0" ixz="0" iyy="3.7178e-06" iyz="0" izz="2.5242e-05"/>
    </inertial>
    <visual>
      <origin rpy="0 0 0" xyz="0 0 0"/>
      <geometry>
        <mesh filename="package://cyton_gamma_1500_minicam_description/meshes/cam_bracket.dae"/>
      </geometry>
    </visual>
    <collision>
        <origin xyz="0.0 0.0 0.0"/>
        <geometry>
          <box size="0.03512 0.04821 0.07179"/>
        </geometry>
      </collision>
  </link>

 <joint name="left_arm_camera_joint" type="fixed">
    <parent link="left_arm_camera_bracket"/>
    <child link="left_arm_camera"/>
    <origin rpy="0 -1.57 0" xyz="0.0 -0.028 -0.005"/>	
  </joint>
  <link name="left_arm_camera">
    <inertial>
      <origin rpy="0 0 0" xyz="0 0 0"/>
      <mass value="0.085"/>
      <!-- inretia tensor for solid cuboid: m=0.085, h=0.065, w=0.024, d=0.024 -->
      <inertia ixx="3.4007e-05" ixy="0" ixz="0" iyy="3.4007e-05" iyz="0" izz="8.16e-06"/>
    </inertial>
    <visual>
      <origin rpy="0 0 0" xyz="0 0 0"/>
      <geometry>
        <!-- <box size="0.031 0.028 0.063"/>		 -->
		<box size="0.063 0.028 0.031"/>	
      </geometry>
      <material name="blackish">
        <color rgba="0.2 0.2 0.2 1"/>
      </material>
    </visual>
    <collision>
      <origin rpy="0 0 0" xyz="0 0 0"/>
      <geometry>
        <!-- <box size="0.036 0.045 0.063"/>	 -->
		<box size="0.063 0.045  0.036"/>
      </geometry>
    </collision>
  </link>


  <!-- PTU -->

  <joint name="ptu_joint" type="fixed">
    <parent link="base_link"/>
    <child link="ptu_base_plate_link"/>
    <origin rpy="0 0 0" xyz="0.02 0 1.1075"/>
  </joint>
  <link name="ptu_base_plate_link">
    <inertial>
      <origin rpy="0 0 0" xyz="-0.034 0 0"/>
      <mass value="0.07"/>
      <!-- inretia tensor for solid cuboid: m=0.07, h=0.005, w=0.142, d=0.17 -->
      <inertia ixx="1.1777e-04" ixy="0" ixz="0" iyy="1.6873e-04" iyz="0" izz="2.8621e-04"/>
    </inertial>
    <visual>
      <origin rpy="0 0 0" xyz="-0.035 0 0.0025"/>
      <geometry>
        <box size="0.17 0.142 0.005"/>
      </geometry>
      <material name="black">
        <color rgba="0.2 0.2 0.2 1"/>
      </material>
    </visual>
  </link>

  <joint name="ptu_base_plate_joint" type="fixed">
    <parent link="ptu_base_plate_link"/>
    <child link="ptu_base_link"/>
    <origin rpy="0 0 0" xyz="0.0 0.0 0.0"/>
  </joint>
  
  
  <link name="ptu_base_link">
  </link>

  <joint name="ptu_base_joint" type="fixed">
    <parent link="ptu_base_link"/>
    <child link="ptu_pan_link"/>
    <origin rpy="0 0 0" xyz="0.0 0 0.005"/>
  </joint>
  
  <link name="ptu_pan_link">
    <inertial>
      <origin rpy="0 0 0" xyz="0 0 0.06"/>
      <mass value="0.13"/>
      <!-- inretia tensor for solid cuboid: m=0.13, h=0.07, w=0.046, d=0.105 -->
      <inertia ixx="7.6006e-05" ixy="0" ixz="0" iyy="1.4136e-04" iyz="0" izz="1.7892e-04"/>
    </inertial>
    <visual>
      <origin rpy="0 0 0" xyz="0 0.0 0.025"/>
      <geometry>
        <mesh filename="package://dp_ptu_46_description/meshes/pan.dae"/>
      </geometry>
    </visual>
    <collision>
      <origin xyz="0 0.0115 0.047"/>
      <geometry>
        <box size="0.154 0.177 0.094"/>
      </geometry>
    </collision>
  </link>

  <joint name="ptu_pan_joint" type="revolute">
    <parent link="ptu_base_link"/>
    <child link="ptu_tilt_link"/>
    <origin rpy="0 0 0" xyz="-0.00436 -0.0067 0.03"/>
    <limit effort="100.0" lower="-2.775" upper="2.775" velocity="1.0"/>
    <axis xyz="0 0 1"/>
  </joint>
  <link name="ptu_tilt_link">
    <inertial>
      <origin rpy="0 0 0" xyz="-0.03 0 0.05"/>
      <mass value="0.13"/>
      <!-- inretia tensor for solid cuboid: m=0.13, h=0.07, w=0.046, d=0.105 -->
      <inertia ixx="7.6006e-05" ixy="0" ixz="0" iyy="1.7252e-04" iyz="0" izz="1.4136e-04"/>
    </inertial>
    <visual>
      <origin rpy="0 0 0" xyz="0.00436 0.0067 0.0"/>
      <geometry>
        <mesh filename="package://dp_ptu_46_description/meshes/tilt.dae"/>
      </geometry>
    </visual>
    <collision>
      <origin xyz="0 0.0115 0.047"/>
      <geometry>
        <box size="0.154 0.177 0.094"/>
      </geometry>
    </collision>
  </link>

  <joint name="ptu_tilt_joint" type="revolute">
    <parent link="ptu_tilt_link"/>
    <child link="ptu_mount_link"/>
    <origin rpy="0 0 0" xyz="0.0 0 0.0659"/>
    <limit effort="100.0" lower="-1.396" upper="0.541" velocity="1.0"/>
    <axis xyz="0 -1 0"/>
  </joint>
  <link name="ptu_mount_link">
    <inertial>
      <origin rpy="0 0 0" xyz="0 0 0.036"/>
      <mass value="0.07"/>
      <!-- inretia tensor for solid cuboid: m=0.07, h=0.007, w=0.052, d=0.025 -->
      <inertia ixx="1.6059e-05" ixy="0" ixz="0" iyy="3.9316e-06" iyz="0" izz="1.9419e-05"/>
    </inertial>
    <visual>
      <origin rpy="0 0 0" xyz="0.00436 0.0067 -0.0659"/>
      <geometry>
        <mesh filename="package://dp_ptu_46_description/meshes/mount.dae"/>
      </geometry>
    </visual>
    <collision>
      <origin xyz="0 0.0115 0.047"/>
      <geometry>
        <box size="0.154 0.177 0.094"/>
      </geometry>
    </collision>
  </link>

  <!-- Hokuyo lidar -->

  <joint name="hokuyo_base_joint" type="fixed">
    <parent link="base_link"/>
    <child link="hokuyo_link"/>
    <origin rpy="0 0 0" xyz="0.1 0 0.3"/>
  </joint>
  <link name="hokuyo_link">
    <inertial>
      <origin rpy="0 0 0" xyz="0 0 -0.02"/>
      <mass value="0.13"/>
      <!-- inretia tensor for solid cuboid: m=0.13, h=0.07, w=0.05, d=0.05 -->
      <inertia ixx="8.0167e-05" ixy="0" ixz="0" iyy="8.0167e-05" iyz="0" izz="5.4167e-05"/>
    </inertial>
    <visual>
      <origin rpy="0 0 0" xyz="0 0 0"/>
      <geometry>
        <cylinder length="0.0265" radius="0.021"/>
      </geometry>
      <material name="blackish"/>
    </visual>
    <visual>
      <origin rpy="0 0 0" xyz="0 0 -0.034"/>
      <geometry>
        <box size="0.05 0.05 0.041"/>
      </geometry>
      <material name="blackish"/>
    </visual>
    <collision>
      <origin rpy="0 0 0" xyz="0 0 0"/>
      <geometry>
        <cylinder length="0.0265" radius="0.021"/>
      </geometry>
    </collision>
    <collision>
      <origin rpy="0 0 0" xyz="0 0 -0.047"/>
      <geometry>
        <box size="0.05 0.05 0.041"/>
      </geometry>
    </collision>
  </link>

  <!-- Bumblebee 2 -->

  <joint name="bumblebee_joint" type="fixed">
    <parent link="ptu_mount_link"/>
    <child link="bumblebee_link"/>
    <origin rpy="0 0 0" xyz="0 0 0.058"/>
  </joint>
  <link name="bumblebee_link">
    <inertial>
      <origin rpy="0 0 0" xyz="0 0 0"/>
      <mass value="0.342"/>
      <!-- inretia tensor for solid cuboid: m=0.342, h=0.036, w=0.157, d=0.0474 -->
      <inertia ixx="7.3943e-04" ixy="0" ixz="0" iyy="1.0096e-04" iyz="0" izz="7.6653e-04"/>
    </inertial>
    <visual>
      <origin rpy="0 0 0" xyz="0 0 0"/>
      <geometry>
        <box size="0.047 0.157 0.038"/>
      </geometry>
      <material name="golden">
        <color rgba="0.4 0.4 0.1 1"/>
      </material>
    </visual>
  </link>

  <joint name="bumblebee_cameras_joint" type="fixed">
    <parent link="bumblebee_link"/>
    <child link="bumblebee_cameras_link"/>
    <origin rpy="0 0 0" xyz="0 0 0.0"/>
  </joint>
  <link name="bumblebee_cameras_link">
    <visual>
      <origin rpy="0 1.5708 0" xyz="0.024 0.06 0"/>
      <geometry>
        <cylinder length="0.001" radius="0.011"/>
      </geometry>
      <material name="glass">
        <color rgba="1 1 1 0.2"/>
      </material>
    </visual>
    <visual>
      <origin rpy="0 1.5708 0" xyz="0.024 -0.06 0"/>
      <geometry>
        <cylinder length="0.001" radius="0.011"/>
      </geometry>
      <material name="glass"/>
    </visual>
  </link>

  <!-- Asus Xtion Pro Live -->

  <joint name="xtion_joint" type="fixed">
    <parent link="bumblebee_link"/>
    <child link="xtion_link"/>
    <origin rpy="0 0 0" xyz="0 0 0.055"/>
  </joint>
  <link name="xtion_link">
    <inertial>
      <origin rpy="0 0 0" xyz="0 0 0"/>
      <mass value="0.54"/>
      <!-- inretia tensor for solid cuboid: m=0.54, h=0.034, w=0.18, d=0.034 -->
      <inertia ixx="1.51e-03" ixy="0" ixz="0" iyy="1.0404e-04" iyz="0" izz="1.51e-03"/>
    </inertial>
    <visual>
      <origin rpy="0 0 0" xyz="0 0 0"/>
      <geometry>
        <box size="0.036 0.178 0.03"/>
      </geometry>
      <material name="blackish"/>
    </visual>
    <visual>
      <origin rpy="0 0 0" xyz="0 0 -0.025"/>
      <geometry>
        <box size="0.02 0.017 0.02"/>
      </geometry>
      <material name="blackish"/>
    </visual>
    <visual>
      <origin rpy="0 0 0" xyz="0 0 -0.035"/>
      <geometry>
        <box size="0.04 0.1 0.004"/>
      </geometry>
      <material name="blackish"/>
    </visual>
  </link>

 <joint name = "xtion_optical_frame_joint" type="fixed">
    <parent link="xtion_link"/>
    <child link="xtion_optical_frame"/>
    <origin rpy="-1.57 0 -1.57" xyz="0 0 0"/>  
  </joint>
  
  <link name="xtion_optical_frame" >
 </link>     
  
  <!--  -->
  <!-- Transmission -->
  
  <transmission name="wheel_left_joint_trans">
    <type>transmission_interface/SimpleTransmission</type>
    <joint name="wheel_left_joint">
      <hardwareInterface>hardware_interface/VelocityJointInterface</hardwareInterface>
    </joint>
    <actuator name="wheel_left_joint_motor">
      <hardwareInterface>hardware_interface/VelocityJointInterface</hardwareInterface>
	  <mechanicalReduction>1.0</mechanicalReduction>
    </actuator>
  </transmission>
  
  <transmission name="wheel_right_joint_trans">
    <type>transmission_interface/SimpleTransmission</type>
    <joint name="wheel_right_joint">
      <hardwareInterface>hardware_interface/VelocityJointInterface</hardwareInterface>
    </joint>
    <actuator name="wheel_right_joint_motor">
      <hardwareInterface>hardware_interface/VelocityJointInterface</hardwareInterface>
	  <mechanicalReduction>1.0</mechanicalReduction>
    </actuator>
  </transmission>
  
  <transmission name="right_arm_shoulder_roll_trans">
    <type>transmission_interface/SimpleTransmission</type>
    <joint name="right_arm_shoulder_roll_joint">
      <hardwareInterface>hardware_interface/PositionJointInterface</hardwareInterface>
    </joint>
    <actuator name="right_arm_shoulder_roll_motor">
      <hardwareInterface>hardware_interface/PositionJointInterface</hardwareInterface>
	  <mechanicalReduction>1.0</mechanicalReduction>
    </actuator>
  </transmission>
  
  <transmission name="right_arm_shoulder_pitch_trans">
    <type>transmission_interface/SimpleTransmission</type>
    <joint name="right_arm_shoulder_pitch_joint">
      <hardwareInterface>hardware_interface/PositionJointInterface</hardwareInterface>
	  
    </joint>
    <actuator name="right_arm_shoulder_pitch_motor">
      <hardwareInterface>hardware_interface/PositionJointInterface</hardwareInterface>
	  <mechanicalReduction>1.0</mechanicalReduction>
    </actuator>
  </transmission>
  
  <transmission name="right_arm_shoulder_yaw_trans">
    <type>transmission_interface/SimpleTransmission</type>
    <joint name="right_arm_shoulder_yaw_joint">
      <hardwareInterface>hardware_interface/PositionJointInterface</hardwareInterface>
	  
    </joint>
    <actuator name="right_arm_shoulder_yaw_motor">
      <hardwareInterface>hardware_interface/PositionJointInterface</hardwareInterface>
	  <mechanicalReduction>1.0</mechanicalReduction>
    </actuator>
  </transmission>
  
  <transmission name="right_arm_elbow_pitch_trans">
    <type>transmission_interface/SimpleTransmission</type>
    <joint name="right_arm_elbow_pitch_joint">
      <hardwareInterface>hardware_interface/PositionJointInterface</hardwareInterface>
    </joint>
    <actuator name="right_arm_elbow_pitch_motor">
      <hardwareInterface>hardware_interface/PositionJointInterface</hardwareInterface>
	  <mechanicalReduction>1.0</mechanicalReduction>
    </actuator>
  </transmission>
  
  <transmission name="right_arm_elbow_yaw_trans">
    <type>transmission_interface/SimpleTransmission</type>
    <joint name="right_arm_elbow_yaw_joint">
      <hardwareInterface>hardware_interface/PositionJointInterface</hardwareInterface>
    </joint>
    <actuator name="right_arm_elbow_yaw_motor">
      <hardwareInterface>hardware_interface/PositionJointInterface</hardwareInterface>
	  <mechanicalReduction>1.0</mechanicalReduction>
    </actuator>
  </transmission>
  
  <transmission name="right_arm_wrist_pitch_trans">
    <type>transmission_interface/SimpleTransmission</type>
    <joint name="right_arm_wrist_pitch_joint">
      <hardwareInterface>hardware_interface/PositionJointInterface</hardwareInterface>
    </joint>
    <actuator name="right_arm_wrist_pitch_motor">
      <hardwareInterface>hardware_interface/PositionJointInterface</hardwareInterface>
	  <mechanicalReduction>1.0</mechanicalReduction>
    </actuator>
  </transmission>
  
  <transmission name="right_arm_wrist_roll_trans">
    <type>transmission_interface/SimpleTransmission</type>
    <joint name="right_arm_wrist_roll_joint">
      <hardwareInterface>hardware_interface/PositionJointInterface</hardwareInterface>
    </joint>
    <actuator name="right_arm_wrist_roll_motor">
      <hardwareInterface>hardware_interface/PositionJointInterface</hardwareInterface>
	  <mechanicalReduction>1.0</mechanicalReduction>
    </actuator>
  </transmission>
  
  <transmission name="right_arm_gripper_joint_trans">
    <type>transmission_interface/SimpleTransmission</type>
    <joint name="right_arm_gripper_joint">
      <hardwareInterface>hardware_interface/PositionJointInterface</hardwareInterface>
    </joint>
    <actuator name="right_arm_gripper_motor">
      <hardwareInterface>hardware_interface/PositionJointInterface</hardwareInterface>
	  <mechanicalReduction>1.0</mechanicalReduction>
    </actuator>
  </transmission>
  <!--
  <transmission name="right_arm_gripper_joint2_trans">
    <type>transmission_interface/SimpleTransmission</type>
    <joint name="right_arm_gripper_joint2">
      <hardwareInterface>hardware_interface/PositionJointInterface</hardwareInterface>
    </joint>
    <actuator name="right_arm_gripper_joint2_motor">
      <hardwareInterface>hardware_interface/PositionJointInterface</hardwareInterface>
    </actuator>
  </transmission>
  
  -->

  <!-- Left Arm Starts -->

  <transmission name="left_arm_shoulder_roll_trans">
    <type>transmission_interface/SimpleTransmission</type>
    <joint name="left_arm_shoulder_roll_joint">
      <hardwareInterface>hardware_interface/PositionJointInterface</hardwareInterface>
    </joint>
    <actuator name="left_arm_shoulder_roll_motor">
      <hardwareInterface>hardware_interface/PositionJointInterface</hardwareInterface>
	  <mechanicalReduction>1.0</mechanicalReduction>
    </actuator>
  </transmission>
  
  <transmission name="left_arm_shoulder_pitch_trans">
    <type>transmission_interface/SimpleTransmission</type>
    <joint name="left_arm_shoulder_pitch_joint">
      <hardwareInterface>hardware_interface/PositionJointInterface</hardwareInterface>
    </joint>
    <actuator name="left_arm_shoulder_pitch_motor">
      <hardwareInterface>hardware_interface/PositionJointInterface</hardwareInterface>
	  <mechanicalReduction>1.0</mechanicalReduction>
    </actuator>
  </transmission>
  
  <transmission name="left_arm_shoulder_yaw_trans">
    <type>transmission_interface/SimpleTransmission</type>
    <joint name="left_arm_shoulder_yaw_joint">
      <hardwareInterface>hardware_interface/PositionJointInterface</hardwareInterface>
    </joint>
    <actuator name="left_arm_shoulder_yaw_motor">
      <hardwareInterface>hardware_interface/PositionJointInterface</hardwareInterface>
	  <mechanicalReduction>1.0</mechanicalReduction>
    </actuator>
  </transmission>
  
  <transmission name="left_arm_elbow_pitch_trans">
    <type>transmission_interface/SimpleTransmission</type>
    <joint name="left_arm_elbow_pitch_joint">
      <hardwareInterface>hardware_interface/PositionJointInterface</hardwareInterface>
    </joint>
    <actuator name="left_arm_elbow_pitch_motor">
      <hardwareInterface>hardware_interface/PositionJointInterface</hardwareInterface>
	  <mechanicalReduction>1.0</mechanicalReduction>
    </actuator>
  </transmission>
  
  <transmission name="left_arm_elbow_yaw_trans">
    <type>transmission_interface/SimpleTransmission</type>
    <joint name="left_arm_elbow_yaw_joint">
      <hardwareInterface>hardware_interface/PositionJointInterface</hardwareInterface>
    </joint>
    <actuator name="left_arm_elbow_yaw_motor">
      <hardwareInterface>hardware_interface/PositionJointInterface</hardwareInterface>
	  <mechanicalReduction>1.0</mechanicalReduction>
    </actuator>
  </transmission>
  
  <transmission name="left_arm_wrist_pitch_trans">
    <type>transmission_interface/SimpleTransmission</type>
    <joint name="left_arm_wrist_pitch_joint">
      <hardwareInterface>hardware_interface/PositionJointInterface</hardwareInterface>
    </joint>
    <actuator name="left_arm_wrist_pitch_motor">
      <hardwareInterface>hardware_interface/PositionJointInterface</hardwareInterface>
	  <mechanicalReduction>1.0</mechanicalReduction>
    </actuator>
  </transmission>
  
  <transmission name="left_arm_wrist_roll_trans">
    <type>transmission_interface/SimpleTransmission</type>
    <joint name="left_arm_wrist_roll_joint">
      <hardwareInterface>hardware_interface/PositionJointInterface</hardwareInterface>
    </joint>
    <actuator name="left_arm_wrist_roll_motor">
      <hardwareInterface>hardware_interface/PositionJointInterface</hardwareInterface>
	  <mechanicalReduction>1.0</mechanicalReduction>
    </actuator>
  </transmission>
  
  <transmission name="left_arm_gripper_joint_trans">
    <type>transmission_interface/SimpleTransmission</type>
    <joint name="left_arm_gripper_joint">
      <hardwareInterface>hardware_interface/PositionJointInterface</hardwareInterface>
    </joint>
    <actuator name="left_arm_gripper_motor">
      <hardwareInterface>hardware_interface/PositionJointInterface</hardwareInterface>
	  <mechanicalReduction>1.0</mechanicalReduction>
    </actuator>
  </transmission>
  <!--
  <transmission name="left_arm_gripper_joint2_trans">
    <type>transmission_interface/SimpleTransmission</type>
    <joint name="left_arm_gripper_joint2">
      <hardwareInterface>hardware_interface/PositionJointInterface</hardwareInterface>
    </joint>
    <actuator name="left_arm_gripper_joint2_motor">
      <hardwareInterface>hardware_interface/PositionJointInterface</hardwareInterface>
    </actuator>
  </transmission>
  
  -->
  <!-- PTU -->
  
  
  <transmission name="ptu_pan_joint_trans">
    <type>transmission_interface/SimpleTransmission</type>
    <joint name="ptu_pan_joint">
      <hardwareInterface>hardware_interface/PositionJointInterface</hardwareInterface>
    </joint>
    <actuator name="ptu_pan_joint_motor">
      <hardwareInterface>hardware_interface/PositionJointInterface</hardwareInterface>
	  <mechanicalReduction>1.0</mechanicalReduction>
    </actuator>
  </transmission>
  
  
  <transmission name="ptu_tilt_joint_trans">
    <type>transmission_interface/SimpleTransmission</type>
    <joint name="ptu_tilt_joint">
      <hardwareInterface>hardware_interface/PositionJointInterface</hardwareInterface>
    </joint>
    <actuator name="ptu_tilt_joint_motor">
      <hardwareInterface>hardware_interface/PositionJointInterface</hardwareInterface>
	  <mechanicalReduction>1.0</mechanicalReduction>
    </actuator>
  </transmission>
  
  
  
  <!-- Gazebo Simulation Settings -->
  
  <!--gazebo>
    <static>false</static>
    <plugin name="gazebo_ros_control" filename="libgazebo_ros_control.so">
      <robotNamespace>/</robotNamespace>
      <robotSimType>gazebo_ros_control/DefaultRobotHWSim</robotSimType>
      <legacyModeNS>true</legacyModeNS>
    </plugin>
  </gazebo-->
  
  <gazebo>
    <plugin name="gazebo_ros_control" filename="libgazebo_ros_control.so">
		<!-- <publishTf>1</publishTf> -->
		<robotNamespace>/phoebe</robotNamespace>
		<robotSimType>gazebo_ros_control/DefaultRobotHWSim</robotSimType>
		<!-- <legacyModeNS>true</legacyModeNS> -->
	
	</plugin>
	
<!-- 	<plugin name="joint_state_publisher" filename="libgazebo_ros_joint_state_publisher.so"> 
      <updateRate>50</updateRate>
    </plugin>

	<plugin filename="libgazebo_ros_p3d.so" name="gazebo_ros_p3d">
      <bodyName>base_link</bodyName>
      <topicName>ground_truth_odom</topicName>
      <alwaysOn>true</alwaysOn>
      <updateRate>100.0</updateRate>
    </plugin>	 -->
  </gazebo>
  
  <!-- <gazebo>
    <plugin filename="libgazebo_ros_force.so" name="gazebo_ros_force">
      <bodyName>base_link</bodyName>
      <topicName>base_link_wrench</topicName>
    </plugin>
  </gazebo>
  <gazebo>
    <plugin filename="libgazebo_world_odometry.so" name="gazebo_ros_odometry">
      <frameName>base_link</frameName>
      <topicName>floating_base_pose_simulated</topicName>
    </plugin>
  </gazebo>
  
  <gazebo>
    <plugin filename="libroboticsgroup_gazebo_mimic_joint_plugin.so" name="right_finger_mimic_joint_plugin">
      <joint>right_arm_gripper_joint</joint>
      <mimicJoint>right_arm_gripper_joint2</mimicJoint>
      <multiplier>-1</multiplier>
      <maxEffort>100.0</maxEffort>
    </plugin>
  </gazebo>
  <gazebo>
    <plugin filename="libroboticsgroup_gazebo_mimic_joint_plugin.so" name="left_finger_mimic_joint_plugin">
      <joint>left_arm_gripper_joint</joint>
      <mimicJoint>left_arm_gripper_joint2</mimicJoint>
      <multiplier>-1</multiplier>
      <maxEffort>100.0</maxEffort>
    </plugin>
  </gazebo> -->
  
  
  <!-- <gazebo>
    <plugin name="joint_state_publisher"
            filename="libgazebo_ros_joint_state_publisher.so">
      
    </plugin>
  </gazebo> -->
  
  
  
  <!-- Links -->
  <gazebo reference="base_link">
        <kp>1e+13</kp>
        <kd>1</kd>
        <mu1>1.0</mu1>																																																																																																																																																																																																																																																																																																																																																																																																																																																																																																																																																																																																																																																																																																																																																																							<mu2>10.0</mu2>
        <material>Gazebo/Grey</material>
  </gazebo>
  <gazebo reference="wheel_left">
          <mu1 value="220.0"/>
          <mu2 value="100.0"/>
          <kp>1e+13</kp>
          <kd>1</kd>
        <material>Gazebo/White</material>
  </gazebo>
  
  <gazebo reference="wheel_right">
        <mu1 value="220.0"/>
          <mu2 value="100.0"/>
          <kp>1e+13</kp>
          <kd>1</kd>
        <material>Gazebo/White</material>
  </gazebo>
  
  <gazebo reference="right_arm_shoulder_pitch">
    <mu1>0.9</mu1>
    <mu2>0.9</mu2>
	<material>Gazebo/Black</material>
  </gazebo>
  
  <gazebo reference="right_arm_shoulder_roll">
    <mu1>0.9</mu1>
    <mu2>0.9</mu2>
	<material>Gazebo/Black</material>
  </gazebo>
  
  <gazebo reference="right_arm_shoulder_yaw">
    <mu1>0.9</mu1>
    <mu2>0.9</mu2>
	<material>Gazebo/Black</material>
  </gazebo>
  
  <gazebo reference="right_arm_elbow_pitch">
    <mu1>0.9</mu1>
    <mu2>0.9</mu2>
	<material>Gazebo/Black</material>
  </gazebo>
  
  <gazebo reference="right_arm_elbow_yaw">
    <mu1>0.9</mu1>
    <mu2>0.9</mu2>
	<material>Gazebo/Black</material>
  </gazebo>
  
  <gazebo reference="right_arm_camera">
    <mu1>0.9</mu1>
    <mu2>0.9</mu2>
	<material>Gazebo/Black</material>
  </gazebo>
  
  <gazebo reference="right_arm_gripper_finger1">
    <mu1>0.9</mu1>
    <mu2>0.9</mu2>
	<material>Gazebo/Black</material>
  </gazebo>
  <gazebo reference="right_arm_gripper_finger2">
    <mu1>0.9</mu1>
    <mu2>0.9</mu2>
	<material>Gazebo/Black</material>
  </gazebo>
  
  <gazebo reference="right_arm_wrist_pitch">
    <mu1>0.9</mu1>
    <mu2>0.9</mu2>
	<material>Gazebo/Black</material>
  </gazebo>
  
  <gazebo reference="right_arm_wrist_roll">
    <mu1>0.9</mu1>
    <mu2>0.9</mu2>
	<material>Gazebo/Black</material>
  </gazebo>
  
  
  <gazebo reference="left_arm_shoulder_pitch">
    <mu1>0.9</mu1>
    <mu2>0.9</mu2>
	<material>Gazebo/Black</material>
  </gazebo>
  
  <gazebo reference="left_arm_shoulder_roll">
    <mu1>0.9</mu1>
    <mu2>0.9</mu2>
	<material>Gazebo/Black</material>
  </gazebo>
  
  <gazebo reference="left_arm_shoulder_yaw">
    <mu1>0.9</mu1>
    <mu2>0.9</mu2>
	<material>Gazebo/Black</material>
  </gazebo>
  
  <gazebo reference="left_arm_elbow_pitch">
    <mu1>0.9</mu1>
    <mu2>0.9</mu2>
	<material>Gazebo/Black</material>
  </gazebo>
  
  <gazebo reference="left_arm_elbow_yaw">
    <mu1>0.9</mu1>
    <mu2>0.9</mu2>
	<material>Gazebo/Black</material>
  </gazebo>
  
  <gazebo reference="left_arm_camera">
    <mu1>0.9</mu1>
    <mu2>0.9</mu2>
	<material>Gazebo/Black</material>
  </gazebo>
  
  <gazebo reference="left_arm_gripper_finger1">
    <mu1>0.9</mu1>
    <mu2>0.9</mu2>
	<material>Gazebo/Black</material>
  </gazebo>
  <gazebo reference="left_arm_gripper_finger2">
    <mu1>0.9</mu1>
    <mu2>0.9</mu2>
	<material>Gazebo/Black</material>
  </gazebo>
  
  <gazebo reference="left_arm_wrist_pitch">
    <mu1>0.9</mu1>
    <mu2>0.9</mu2>
	<material>Gazebo/Black</material>
  </gazebo>
  
  <gazebo reference="left_arm_wrist_roll">
    <mu1>0.9</mu1>
    <mu2>0.9</mu2>
	<material>Gazebo/Black</material>
  </gazebo>
  
 <!--  <gazebo>
    <plugin filename="libgazebo_ros_diff_drive.so" name="differential_drive_controller">
      <alwaysOn>true</alwaysOn>
      <updateRate>50</updateRate>
      <leftJoint>wheel_left_joint</leftJoint>
      <rightJoint>wheel_right_joint</rightJoint>
      <wheelSeparation>0.31</wheelSeparation>
      <wheelDiameter>0.19</wheelDiameter>
      <torque>10</torque>
      <commandTopic>cmd_vel</commandTopic>
      <odometryTopic>odom</odometryTopic>
      <odometryFrame>odom</odometryFrame>
      <robotBaseFrame>base_link</robotBaseFrame>
	  <legacyMode>false</legacyMode>
	  <publishWheelTF>true</publishWheelTF>
	  <publishOdomTF>true</publishOdomTF>
	  <publishWheelJointState>true</publishWheelJointState>
	  <publishTf>1</publishTf>
	  <wheelAcceleration>5</wheelAcceleration>
	  <wheelTorque>10</wheelTorque>
	  <odometrySource>world</odometrySource>
	  <rosDebugLevel>na</rosDebugLevel>
    </plugin>
  </gazebo> -->
  
  
  
  <!-- From rrbot -->
  
  <gazebo reference="hokuyo_link">
    <sensor name="head_hokuyo_sensor" type="gpu_ray">
      <pose>0 0 0 0 0 0</pose>
      <visualize>false</visualize>
      <update_rate>40</update_rate>
      <ray>
        <scan>
          <horizontal>
            <samples>720</samples>
            <resolution>1</resolution>
            <min_angle>-1.570796</min_angle>
            <max_angle>1.570796</max_angle>
          </horizontal>
        </scan>
        <range>
          <min>0.10</min>
          <max>30.0</max>
          <resolution>0.01</resolution>
        </range>
        <noise>
          <type>gaussian</type>
          <!-- Noise parameters based on published spec for Hokuyo laser
               achieving "+-30mm" accuracy at range < 10m.  A mean of 0.0m and
               stddev of 0.01m will put 99.7% of samples within 0.03m of the true
               reading. -->
          <mean>0.0</mean>
          <stddev>0.01</stddev>
        </noise>
      </ray>
      <plugin filename="libgazebo_ros_gpu_laser.so" name="gazebo_ros_head_hokuyo_controller">
        <topicName>/phoebe/laser/scan</topicName>
        <frameName>hokuyo_link</frameName>
      </plugin>
    </sensor>
  </gazebo>
  
  <gazebo reference="right_arm_camera">
    <sensor name="camera1" type="camera">
      <update_rate>30.0</update_rate>
      <camera name="head">
        <horizontal_fov>1.3962634</horizontal_fov>
        <image>
          <width>800</width>
          <height>800</height>
          <format>R8G8B8</format>
        </image>
        <clip>
          <near>0.02</near>
          <far>300</far>
        </clip>
        <noise>
          <type>gaussian</type>
          <!-- Noise is sampled independently per pixel on each frame.  
               That pixel's noise value is added to each of its color
               channels, which at that point lie in the range [0,1]. -->
          <mean>0.0</mean>
          <stddev>0.007</stddev>
        </noise>
      </camera>
      <plugin filename="libgazebo_ros_camera.so" name="camera_controller">
        <alwaysOn>true</alwaysOn>
        <updateRate>0.0</updateRate>
        <cameraName>phoebe/camera1</cameraName>
        <imageTopicName>image_raw</imageTopicName>
        <cameraInfoTopicName>camera_info</cameraInfoTopicName>
        <frameName>right_arm_camera</frameName>
        <hackBaseline>0.07</hackBaseline>
        <distortionK1>0.0</distortionK1>
        <distortionK2>0.0</distortionK2>
        <distortionK3>0.0</distortionK3>
        <distortionT1>0.0</distortionT1>
        <distortionT2>0.0</distortionT2>
      </plugin>
    </sensor>
  </gazebo>
  
  
  
  
 <!-- Gazebo  Cameras --> 
  <!-- <gazebo reference="xtion_link"> -->
  <!-- <sensor name="xtion_link_camera" type="depth"> -->
    <!-- <update_rate>30</update_rate> -->
    <!-- <camera> -->
      <!-- <horizontal_fov>1.01229096</horizontal_fov> <!-- in radians --> -->
      <!-- <image> -->
        <!-- <width>640</width> -->
        <!-- <height>480</height> -->
        <!-- <format>R8G8B8</format> -->
      <!-- </image> -->
      <!-- <clip> -->
        <!-- <near>0.08</near> -->
        <!-- <far>6.5</far> -->
      <!-- </clip> -->
    <!-- </camera> -->
    <!-- <plugin name="xtion_link_controller" filename="libgazebo_ros_openni_kinect.so"> -->
      <!-- <baseline>0.2</baseline> -->
      <!-- <alwaysOn>true</alwaysOn> -->
      <!-- <updateRate>0</updateRate> -->
      <!-- <cameraName>xtion</cameraName> -->
      <!-- <imageTopicName>/phoebe/xtion/color/image_raw</imageTopicName> -->
      <!-- <cameraInfoTopicName>/phoebe/xtion/color/camera_info</cameraInfoTopicName> -->
      <!-- <depthImageTopicName>/phoebe/xtion/depth/image_raw</depthImageTopicName> -->
      <!-- <depthImageInfoTopicName>/xtion/depth/camera_info</depthImageInfoTopicName> -->
      <!-- <pointCloudTopicName>/phoebe/xtion/depth/points</pointCloudTopicName> -->
      <!-- <frameName>xtion_optical_frame</frameName> -->
      <!-- <pointCloudCutoff>0.5</pointCloudCutoff> -->
      <!-- <pointCloudCutoffMax>3.5</pointCloudCutoffMax> -->
      <!-- <distortionK1>0.00000001</distortionK1> -->
      <!-- <distortionK2>0.00000001</distortionK2> -->
      <!-- <distortionK3>0.00000001</distortionK3> -->
      <!-- <distortionT1>0.00000001</distortionT1> -->
      <!-- <distortionT2>0.00000001</distortionT2> -->
      <!-- <CxPrime>0</CxPrime> -->
      <!-- <Cx>0</Cx> -->
      <!-- <Cy>0</Cy> -->
      <!-- <focalLength>0</focalLength>  <!--577.2 --> 
      <!-- <hackBaseline>0</hackBaseline> -->
    <!-- </plugin> -->
  <!-- </sensor> -->
<!-- </gazebo> -->


<!-- hokuyo -->
  <!-- <gazebo reference="hokuyo_link"> -->
	<!-- <material>Gazebo/Black</material> -->
    <!-- <sensor type="ray" name="head_hokuyo_sensor"> -->
      <!-- <pose>0 0 0 0 0 0</pose> -->
      <!-- <visualize>false</visualize> -->
      <!-- <update_rate>20</update_rate> -->
      <!-- <ray> -->
        <!-- <scan> -->
          <!-- <horizontal> -->
            <!-- <samples>720</samples> -->
            <!-- <resolution>1</resolution> -->
            <!-- <min_angle>-1.570796</min_angle> -->
            <!-- <max_angle>1.570796</max_angle> -->
          <!-- </horizontal> -->
        <!-- </scan> -->
        <!-- <range> -->
          <!-- <min>0.10</min> -->
          <!-- <max>30.0</max> -->
          <!-- <resolution>0.01</resolution> -->
        <!-- </range> -->
        <!-- <noise> -->
          <!-- <type>gaussian</type> -->
          <!-- Noise parameters based on published spec for Hokuyo laser
               achieving "+-30mm" accuracy at range < 10m.  A mean of 0.0m and
               stddev of 0.01m will put 99.7% of samples within 0.03m of the true
               reading. -->
          <!-- <mean>0.0</mean> -->
          <!-- <stddev>0.01</stddev> -->
        <!-- </noise> -->
      <!-- </ray> -->
      <!-- <plugin name="gazebo_ros_head_hokuyo_controller" filename="libgazebo_ros_laser.so"> -->
        <!-- <topicName>/phoebe/laser/scan</topicName> -->
        <!-- <frameName>hokuyo_link</frameName> -->
      <!-- </plugin> -->
    <!-- </sensor> -->
  <!-- </gazebo> -->
  
  
  <!-- <gazebo reference="bumblebee_link"> -->
    <!-- <sensor name="gazebo_stereo_camera" type="multicamera"> -->
      <!-- <update_rate>25.0</update_rate> -->
      <!-- <camera name="left"> -->
	    <!-- <pose>0 0.065 0 0 0 0</pose> -->
        <!-- <horizontal_fov>1.69297</horizontal_fov> -->
        <!-- <image> -->
          <!-- <width>640 </width> -->
          <!-- <height> 480</height> -->
          <!-- <format>B8G8R8</format> -->
        <!-- </image> -->
        <!-- <clip> -->
          <!-- <near>0.01</near> -->
          <!-- <far>100</far> -->
        <!-- </clip> -->
      <!-- </camera> -->
      <!-- <camera name="right"> -->
        <!-- <pose>0 -0.065 0 0 0 0</pose> -->
        <!-- the pose is wrt /stereo_link which is the parent of stereo_optical_frame -->
        <!-- <horizontal_fov>1.69297</horizontal_fov> -->
        <!-- <image> -->
          <!-- <width>640 </width> -->
          <!-- <height> 480</height> -->
          <!-- <format>B8G8R8</format> -->
        <!-- </image> -->
        <!-- <clip> -->
          <!-- <near>0.01</near> -->
          <!-- <far>10</far> -->
        <!-- </clip> -->
      <!-- </camera> -->
      <!-- <plugin filename="libgazebo_ros_multicamera.so" name="stereo_camera_controller"> -->
        <!-- <alwaysOn>true</alwaysOn> -->
        <!-- <updateRate>0.0</updateRate> -->
        <!-- <cameraName>bumblebee</cameraName> -->
        <!-- <imageTopicName>/phoebe/bumblebee/image</imageTopicName> -->
        <!-- <cameraInfoTopicName>/bumblebee/camera_info</cameraInfoTopicName> -->
        <!-- <frameName>bumblebee_link</frameName> -->
        <!-- <hackBaseline>0.0</hackBaseline> -->
        <!-- <CxPrime>0</CxPrime> -->
        <!-- <Cx>0</Cx> -->
        <!-- <Cy>0</Cy> -->
        <!-- <focalLength>0</focalLength> <!-- 283.0 --> -->
        <!-- image_width / (2*tan(hfov_radian /2)) -->
        <!-- <distortionK1>0.0</distortionK1> -->
        <!-- <distortionK2>0.0</distortionK2> -->
        <!-- <distortionK3>0.0</distortionK3> -->
        <!-- <distortionT1>0.0</distortionT1> -->
        <!-- <distortionT2>0.0</distortionT2> -->
      <!-- </plugin> -->
    <!-- </sensor> -->
   <!-- </gazebo> -->
   
   <!-- Camera Right Arm -->
   <!-- <gazebo reference="right_arm_camera"> -->
    <!-- <sensor type="camera" name="right_arm_camera"> -->
      <!-- <update_rate>30.0</update_rate> -->
      <!-- <camera name="right_arm_camera"> -->
        <!-- <horizontal_fov>1.3962634</horizontal_fov>  <!-- 25.9deg, vertical 0.279253 rad = 16 deg-->   -->
       	<!-- <image> -->
          <!-- <width>1280</width> -->
          <!-- <height>1024</height> -->
          <!-- <format>R8G8B8</format> -->
        <!-- </image> -->
        <!-- <clip> -->
          <!-- <near>0.05</near> -->
		  <!-- <far>3</far> -->
        <!-- </clip> -->
        
      <!-- </camera> -->
      <!-- <plugin name="camera_controller" filename="libgazebo_ros_camera.so"> -->
        <!-- <alwaysOn>true</alwaysOn> -->
        <!-- <updateRate>0.0</updateRate> -->
        <!-- <cameraName>right_arm_camera</cameraName> -->
        <!-- <imageTopicName>/phoebe/right_arm_camera/image_raw</imageTopicName> -->
        <!-- <cameraInfoTopicName>/right_arm_camera/camera_info</cameraInfoTopicName> -->
        <!-- <frameName>right_arm_camera</frameName> -->
        <!-- <hackBaseline>0.0</hackBaseline> -->
        <!-- <distortionK1>0.0</distortionK1> -->
        <!-- <distortionK2>0.0</distortionK2> -->
        <!-- <distortionK3>0.0</distortionK3> -->
        <!-- <distortionT1>0.0</distortionT1> -->
        <!-- <distortionT2>0.0</distortionT2> -->
      <!-- </plugin> -->
    <!-- </sensor> -->
  <!-- </gazebo> -->
  
  <!-- Camera Left Arm -->
  <!-- <gazebo reference="left_arm_camera"> -->
    <!-- <sensor type="camera" name="left_arm_camera"> -->
      <!-- <update_rate>30.0</update_rate> -->
      <!-- <camera name="left_arm_camera"> -->
        <!-- <horizontal_fov>1.3962634</horizontal_fov> -->
        <!-- <image> -->
          <!-- <width>1280</width> -->
          <!-- <height>1024</height> -->
          <!-- <format>R8G8B8</format> -->
        <!-- </image> -->
        <!-- <clip> -->
           <!-- <near>0.05</near> -->
		   <!-- <far>3</far> -->
        <!-- </clip> -->
        
      <!-- </camera> -->
      <!-- <plugin name="camera_controller" filename="libgazebo_ros_camera.so"> -->
        <!-- <alwaysOn>true</alwaysOn> -->
        <!-- <updateRate>0.0</updateRate> -->
        <!-- <cameraName>left_arm_camera</cameraName> -->
        <!-- <imageTopicName>/phoebe/left_arm_camera/image_raw</imageTopicName> -->
        <!-- <cameraInfoTopicName>/left_arm_camera/camera_info</cameraInfoTopicName> -->
        <!-- <frameName>left_arm_camera</frameName> -->
        <!-- <hackBaseline>0.0</hackBaseline> -->
        <!-- <distortionK1>0.0</distortionK1> -->
        <!-- <distortionK2>0.0</distortionK2> -->
        <!-- <distortionK3>0.0</distortionK3> -->
        <!-- <distortionT1>0.0</distortionT1> -->
        <!-- <distortionT2>0.0</distortionT2> -->
      <!-- </plugin> -->
    <!-- </sensor> -->
   <!-- </gazebo>  -->

</robot>
