<?xml version="1.0"?>
<robot xmlns:xacro="http://www.ros.org/wiki/xacro" name="phoebe">
 <!-- <xacro:include filename="$(find cyton_gamma_1500_minicam_description)/cyton_gamma_1500_minicam_macros.urdf.xacro" /> -->
  <xacro:include filename="$(find cyton_gamma_1500_description)/urdf/cyton_gamma_1500_macros.urdf.xacro" />
  <xacro:include filename="$(find dp_ptu_46_description)/dp_ptu_46_macros.urdf.xacro" />
  <xacro:include filename="$(find phoebe_description)/urdf/phoebe.gazebo" />
  
  <link name="base_footprint"/>
    
  <joint name="base_joint" type="fixed">
      <origin xyz="0 0 0.0012" rpy="0 0 0" />
      <parent link="base_footprint"/>
      <child link="base_link" />
  </joint> 
  
  
  <link name="base_link">
    <inertial>
      <origin rpy="0 0 0" xyz="-0.040872 0.0 0.56"/>
      <mass value="12"/>
      <!-- inretia tensor for solid cuboid: m=12, h=1.12, d=0.49, w=0.41 -->
      <inertia ixx="1.4225" ixy="0" ixz="0" iyy="1.4945" iyz="0" izz="0.4082"/>
    </inertial>
	<visual>
      <origin xyz="0 0 0" rpy="0 0 0"/>
      <geometry>
        <mesh filename="package://phoebe_description/meshes/phoebe.dae"/>
      </geometry>
    </visual>
    <collision>
      <origin xyz="0 0 0" rpy="0 0 0"/>
      <geometry>
        <mesh filename="package://phoebe_description/meshes/phoebe.dae"/>
      </geometry>
    </collision>
  </link>
  
  <joint name="wheel_rear_joint" type="continuous">
     <origin rpy="0 0 0" xyz="-0.29 0.0 0.020"/>
    <parent link="base_link"/>
    <child link="wheel_rear"/>   
	<axis rpy="0 0 0" xyz="0 1 0"/>
    <limit effort="10000" velocity="1000"/>
    <joint_properties damping="0.0" friction="0.0"/>
    
  </joint>

  <link name="wheel_rear">
    <inertial>
      <!--origin rpy="0 0 0" xyz="0 0 0"/-->
	  <origin rpy="0 1.5708 1.5708" xyz="0 0 0"/>
      <mass value="0.25"/>
      <!-- inretia tensor for solid cylinder: m=0.5, h=0.05, r=0.095 -->
      <inertia ixx="1.232291667e-03" ixy="0" ixz="0" iyy="1.232291667e-03" iyz="0" izz="2.25625e-03"/>
    </inertial>
    <visual>
      <origin rpy="0 1.5707 1.5707" xyz="0 0 0"/>
      <geometry>
        <cylinder length="0.025" radius="0.02"/>
      </geometry>
      <material name="blackish">
        <color rgba="0.2 0.2 0.2 1"/>
      </material>
    </visual>
    <collision>
      <origin rpy="0 1.5707 1.5707" xyz="0 0 0"/>
      <geometry>
        <cylinder length="0.025" radius="0.02"/>
      </geometry>
    </collision>
  </link>
  
  
  <joint name="wheel_front_joint" type="continuous">
    <parent link="base_link"/>
    <child link="wheel_front"/>
    <origin rpy="0 0 0" xyz="0.206 0 0.020"/>
	<axis rpy="0 0 0" xyz="0 1 0"/>
    <limit effort="10000" velocity="1000"/>
    <joint_properties damping="0.0" friction="0.0"/>    
  </joint>
  
  <link name="wheel_front">
    <inertial>
      <!--origin rpy="0 0 0" xyz="0 0 0"/-->
	  <origin rpy="0 1.5708 1.5708" xyz="0 0 0"/>
      <mass value="0.25"/>
      
      <inertia ixx="1.232291667e-03" ixy="0" ixz="0" iyy="1.232291667e-03" iyz="0" izz="2.25625e-03"/>
    </inertial>
    <visual>
     <origin rpy="0 1.5707 1.5707" xyz="0 0 0"/>
     <geometry>
        <cylinder length="0.025" radius="0.02"/>
      </geometry>
      <material name="blackish"/>
    </visual>
    <collision>
      <origin rpy="0 1.5707 1.5707" xyz="0 0 0"/>
      <geometry>
        <cylinder length="0.025" radius="0.02"/>
      </geometry>
    </collision>
  </link>

  <joint name="wheel_left_joint" type="continuous">
    <parent link="base_link"/>
    <child link="wheel_left"/>
	<!--origin rpy="1.570796 0 0" xyz="0.0 0.18 0.095"/-->
    <origin rpy="0 0 0" xyz="0.0 0.18 0.095"/>
    <!--axis xyz="0 0 1"/-->
	<axis xyz="0 1 0"/>
	<limit effort="10000" velocity="1000"/>
    <joint_properties damping="1.0" friction="1.0"/>
  </joint>

  <link name="wheel_left">
    <inertial>
      <!--origin rpy="0 0 0" xyz="0 0 0"/-->
	  <origin rpy="0 1.5708 1.5708" xyz="0 0 0"/>
      <mass value="0.5"/>
      <!-- inretia tensor for solid cylinder: m=0.5, h=0.05, r=0.095 -->
      <inertia ixx="1.232291667e-03" ixy="0" ixz="0" iyy="1.232291667e-03" iyz="0" izz="2.25625e-03"/>
    </inertial>
    <visual>
      <!--origin rpy="0 0 0" xyz="0 0 0"/-->
	  <origin rpy="0 1.5708 1.5708" xyz="0 0 0"/>
      <geometry>
        <cylinder length="0.05" radius="0.095"/>
      </geometry>
      <material name="blackish">
        <color rgba="0.2 0.2 0.2 1"/>
      </material>
    </visual>
    <collision>
      <!--origin rpy="0 0 0" xyz="0 0 0"/-->
	  <origin rpy="0 1.5707 1.5707" xyz="0 0 0"/>
      <geometry>
        <cylinder length="0.05" radius="0.095"/>
      </geometry>
    </collision>
  </link>

  <joint name="wheel_right_joint" type="continuous">
    <parent link="base_link"/>
    <child link="wheel_right"/>
    <!--origin rpy="1.570796 0 0" xyz="0.0 -0.18 0.095"/-->
	<origin rpy="0 0 0" xyz="0.0 -0.18 0.095"/>
    <!--axis xyz="0 0 1"/-->
	<axis xyz="0 1 0"/>
	<limit effort="10000" velocity="1000"/>
    <joint_properties damping="1.0" friction="1.0"/>
  </joint>
  <link name="wheel_right">
    <inertial>
      <!--origin rpy="0 0 0" xyz="0 0 0"/-->
	  <origin rpy="0 1.5708 1.5708" xyz="0 0 0"/>
      <mass value="0.5"/>
      <!-- inretia tensor for solid cylinder: m=0.5, h=0.05, r=0.095 -->
      <inertia ixx="1.232291667e-03" ixy="0" ixz="0" iyy="1.232291667e-03" iyz="0" izz="2.25625e-03"/>
    </inertial>
    <visual>
      <!--origin rpy="0 0 0" xyz="0 0 0"/-->
	  <origin rpy="0 1.5708 1.5708" xyz="0 0 0"/>
      <geometry>
        <cylinder length="0.05" radius="0.095"/>
      </geometry>
      <material name="blackish"/>
    </visual>
    <collision>
      <!--origin rpy="0 0 0" xyz="0 0 0"/-->
	  <origin rpy="0 1.5708 1.5708" xyz="0 0 0"/>
      <geometry>
        <cylinder length="0.05" radius="0.095"/>
      </geometry>
    </collision>
  </link>

  <!-- Cyton Gamma 1500 models -->
  <!-- Right arm -->
  <joint name="right_arm_joint" type="fixed">
    <parent link="base_link" />
    <child link="right_arm_base_link" />
    <origin xyz="0.067 -0.162 0.8" rpy="1.5708 -1.5708 0" />
  </joint>
 <!--<xacro:cyton_gamma_1500_minicam prefix="right_arm_" virtual_ee="true"/>-->
 <xacro:cyton_gamma_1500 prefix="right_arm_" virtual_ee="true" />

  <!-- Left arm -->
  <joint name="left_arm_joint" type="fixed">
    <parent link="base_link" />
    <child link="left_arm_base_link" />
    <origin xyz="0.067 0.162 0.8" rpy="-1.5708 1.5708 0" />
  </joint>
  <!--<xacro:cyton_gamma_1500_minicam prefix="left_arm_" virtual_ee="true" />-->
  <xacro:cyton_gamma_1500 prefix="left_arm_" virtual_ee="true" />

  <!-- PTU -->
  <joint name="ptu_joint" type="fixed">
    <parent link="base_link" />
    <child link="ptu_base_plate_link" />
    <origin xyz="0.02 0 1.1075" rpy="0 0 0" />
  </joint>
  <xacro:dp_ptu_46 prefix="" plate="true" thickness="0.005" />

  <!-- Hokuyo lidar -->
  <joint name="hokuyo_base_joint" type="fixed">
    <parent link="base_link" />
    <child link="hokuyo_link" />
    <origin xyz="0.1 0 0.3" rpy="0 0 0" />
  </joint>

  <link name="hokuyo_link">
    <inertial>
      <origin rpy="0 0 0" xyz="0 0 -0.02"/>
      <mass value="0.13"/>
      <!-- inretia tensor for solid cuboid: m=0.13, h=0.07, w=0.05, d=0.05 -->
      <inertia ixx="8.0167e-05" ixy="0" ixz="0" iyy="8.0167e-05" iyz="0" izz="5.4167e-05"/>
    </inertial>
	<visual>
      <origin xyz="0 0 0" rpy="0 0 0"/>
      <geometry>
        <cylinder length="0.0265" radius="0.021" />
      </geometry>
      <material name="blackish" />
    </visual>
    <visual>
      <origin xyz="0 0 -0.034" rpy="0 0 0"/>
      <geometry>
        <box size="0.05 0.05 0.041"/>
      </geometry>
      <material name="blackish" />
    </visual>
    <collision>
      <origin xyz="0 0 0" rpy="0 0 0"/>
      <geometry>
        <cylinder length="0.0265" radius="0.021" />
      </geometry>
    </collision>
    <collision>
      <origin xyz="0 0 -0.047" rpy="0 0 0"/>
      <geometry>
        <box size="0.05 0.05 0.041"/>
      </geometry>
    </collision>
  </link>

  <!-- Bumblebee 2 -->
  <joint name="bumblebee_joint" type="fixed">
    <parent link="ptu_mount_link" />
    <child link="bumblebee_link" />
    <origin xyz="0 0 0.058" rpy="0 0 0" />
  </joint>

  <link name="bumblebee_link">
    <inertial>
      <origin rpy="0 0 0" xyz="0 0 0"/>
      <mass value="0.342"/>
      <!-- inretia tensor for solid cuboid: m=0.342, h=0.036, w=0.157, d=0.0474 -->
      <inertia ixx="7.3943e-04" ixy="0" ixz="0" iyy="1.0096e-04" iyz="0" izz="7.6653e-04"/>
    </inertial>
	<visual>
      <origin xyz="0 0 0" rpy="0 0 0"/>
      <geometry>
        <box size="0.047 0.157 0.038"/>
      </geometry>
      <material name="golden">
        <color rgba="0.4 0.4 0.1 1" />
      </material>
    </visual>
  </link>

  <joint name="bumblebee_cameras_joint" type="fixed">
    <parent link="bumblebee_link" />
    <child link="bumblebee_cameras_link" />
    <origin xyz="0 0 0.0" rpy="0 0 0" />
  </joint>

  <link name="bumblebee_cameras_link">
    <visual>
      <origin xyz="0.024 0.06 0" rpy="0 1.5708 0"/>
      <geometry>
        <cylinder length="0.001" radius="0.011" />
      </geometry>
      <material name="glass">
        <color rgba="1 1 1 0.2" />
      </material>
    </visual>
    <visual>
      <origin xyz="0.024 -0.06 0" rpy="0 1.5708 0"/>
      <geometry>
        <cylinder length="0.001" radius="0.011" />
      </geometry>
      <material name="glass" />
    </visual>
  </link>
  
  <!-- Asus Xtion Pro Live -->
  <joint name="xtion_joint" type="fixed">
    <parent link="bumblebee_link" />
    <child link="xtion_link" />
    <origin xyz="0 0 0.055" rpy="0 0 0" />
  </joint>

  <link name="xtion_link">
    <inertial>
      <origin rpy="0 0 0" xyz="0 0 0"/>
      <mass value="0.54"/>
      <!-- inretia tensor for solid cuboid: m=0.54, h=0.034, w=0.18, d=0.034 -->
      <inertia ixx="1.51e-03" ixy="0" ixz="0" iyy="1.0404e-04" iyz="0" izz="1.51e-03"/>
    </inertial>
	<visual>
      <origin xyz="0 0 0" rpy="0 0 0"/>
      <geometry>
        <box size="0.036 0.178 0.03"/>
      </geometry>
      <material name="blackish" />
    </visual>
    <visual>
      <origin xyz="0 0 -0.025" rpy="0 0 0"/>
      <geometry>
        <box size="0.02 0.017 0.02"/>
      </geometry>
      <material name="blackish" />
    </visual>
    <visual>
      <origin xyz="0 0 -0.035" rpy="0 0 0"/>
      <geometry>
        <box size="0.04 0.1 0.004"/>
      </geometry>
      <material name="blackish" />
    </visual>
  </link>
  
  
  <joint name = "xtion_optical_frame_joint" type="fixed">
    <parent link="xtion_link"/>
    <child link="xtion_optical_frame"/>
    <origin rpy="-1.57 0 -1.57" xyz="0 0 0"/>  
  </joint>
  
  <link name="xtion_optical_frame" >
 </link>

  <joint name = "left_optical_frame_joint" type="fixed">
    <parent link="left_arm_camera"/>
    <child link="left_optical_frame"/>
    <origin rpy="0 -1.5708  0" xyz="0 0 0"/>  
  </joint>
  
  <link name="left_optical_frame" >
 </link> 

  <joint name = "right_optical_frame_joint" type="fixed">
    <parent link="right_arm_camera"/>
    <child link="right_optical_frame"/>
    <origin rpy="0  -1.5708 3.14" xyz="0 0 0"/>  
  </joint>
  
  <link name="right_optical_frame" >
 </link>   

</robot>
